INFO 2024-12-23 19:56:39,955 autoreload 15672 1772 Watching for file changes with StatReloader
INFO 2024-12-23 19:56:43,479 basehttp 15672 6372 "GET / HTTP/1.1" 302 0
INFO 2024-12-23 19:56:43,496 basehttp 15672 6372 "GET /login/ HTTP/1.1" 200 4979
INFO 2024-12-23 19:56:43,564 basehttp 15672 6372 "GET /static/css/main.css HTTP/1.1" 304 0
DEBUG 2024-12-23 19:56:43,729 base 15672 6372 Exception while resolving variable 'name' in template 'unknown'.
Traceback (most recent call last):
  File "C:\Python312\Lib\site-packages\django\core\handlers\exception.py", line 55, in inner
    response = get_response(request)
               ^^^^^^^^^^^^^^^^^^^^^
  File "C:\Python312\Lib\site-packages\django\core\handlers\base.py", line 181, in _get_response
    callback, callback_args, callback_kwargs = self.resolve_request(request)
                                               ^^^^^^^^^^^^^^^^^^^^^^^^^^^^^
  File "C:\Python312\Lib\site-packages\django\core\handlers\base.py", line 313, in resolve_request
    resolver_match = resolver.resolve(request.path_info)
                     ^^^^^^^^^^^^^^^^^^^^^^^^^^^^^^^^^^^
  File "C:\Python312\Lib\site-packages\django\urls\resolvers.py", line 705, in resolve
    raise Resolver404({"tried": tried, "path": new_path})
django.urls.exceptions.Resolver404: {'tried': [[<URLResolver <URLPattern list> (admin:admin) 'admin/'>], [<URLResolver <module 'secretary_dash.urls' from 'C:\\Users\\DC\\Desktop\\itec320_project20801530\\itec320_project20801530\\itec320_project\\secretary_dash\\urls.py'> (secretary_dash:secretary_dash) ''>, <URLPattern '' [name='root']>], [<URLResolver <module 'secretary_dash.urls' from 'C:\\Users\\DC\\Desktop\\itec320_project20801530\\itec320_project20801530\\itec320_project\\secretary_dash\\urls.py'> (secretary_dash:secretary_dash) ''>, <URLPattern 'forgot-password/' [name='forgot_password']>], [<URLResolver <module 'secretary_dash.urls' from 'C:\\Users\\DC\\Desktop\\itec320_project20801530\\itec320_project20801530\\itec320_project\\secretary_dash\\urls.py'> (secretary_dash:secretary_dash) ''>, <URLPattern 'reset-password/<str:uidb64>/<str:token>/' [name='reset_password']>], [<URLResolver <module 'secretary_dash.urls' from 'C:\\Users\\DC\\Desktop\\itec320_project20801530\\itec320_project20801530\\itec320_project\\secretary_dash\\urls.py'> (secretary_dash:secretary_dash) ''>, <URLPattern 'doctor/' [name='doctor_dashboard']>], [<URLResolver <module 'secretary_dash.urls' from 'C:\\Users\\DC\\Desktop\\itec320_project20801530\\itec320_project20801530\\itec320_project\\secretary_dash\\urls.py'> (secretary_dash:secretary_dash) ''>, <URLPattern 'doctor/secretaries/' [name='secretary_list']>], [<URLResolver <module 'secretary_dash.urls' from 'C:\\Users\\DC\\Desktop\\itec320_project20801530\\itec320_project20801530\\itec320_project\\secretary_dash\\urls.py'> (secretary_dash:secretary_dash) ''>, <URLPattern 'doctor/secretaries/add/' [name='secretary_create']>], [<URLResolver <module 'secretary_dash.urls' from 'C:\\Users\\DC\\Desktop\\itec320_project20801530\\itec320_project20801530\\itec320_project\\secretary_dash\\urls.py'> (secretary_dash:secretary_dash) ''>, <URLPattern 'doctor/secretaries/<int:pk>/edit/' [name='secretary_edit']>], [<URLResolver <module 'secretary_dash.urls' from 'C:\\Users\\DC\\Desktop\\itec320_project20801530\\itec320_project20801530\\itec320_project\\secretary_dash\\urls.py'> (secretary_dash:secretary_dash) ''>, <URLPattern 'doctor/secretaries/<int:pk>/delete/' [name='secretary_delete']>], [<URLResolver <module 'secretary_dash.urls' from 'C:\\Users\\DC\\Desktop\\itec320_project20801530\\itec320_project20801530\\itec320_project\\secretary_dash\\urls.py'> (secretary_dash:secretary_dash) ''>, <URLPattern 'doctor/busy-hours/' [name='busy_hours_list']>], [<URLResolver <module 'secretary_dash.urls' from 'C:\\Users\\DC\\Desktop\\itec320_project20801530\\itec320_project20801530\\itec320_project\\secretary_dash\\urls.py'> (secretary_dash:secretary_dash) ''>, <URLPattern 'doctor/busy-hours/add/' [name='busy_hours_create']>], [<URLResolver <module 'secretary_dash.urls' from 'C:\\Users\\DC\\Desktop\\itec320_project20801530\\itec320_project20801530\\itec320_project\\secretary_dash\\urls.py'> (secretary_dash:secretary_dash) ''>, <URLPattern 'doctor/busy-hours/<int:pk>/edit/' [name='busy_hours_edit']>], [<URLResolver <module 'secretary_dash.urls' from 'C:\\Users\\DC\\Desktop\\itec320_project20801530\\itec320_project20801530\\itec320_project\\secretary_dash\\urls.py'> (secretary_dash:secretary_dash) ''>, <URLPattern 'doctor/busy-hours/<int:pk>/delete/' [name='busy_hours_delete']>], [<URLResolver <module 'secretary_dash.urls' from 'C:\\Users\\DC\\Desktop\\itec320_project20801530\\itec320_project20801530\\itec320_project\\secretary_dash\\urls.py'> (secretary_dash:secretary_dash) ''>, <URLPattern 'patients/' [name='patient_list']>], [<URLResolver <module 'secretary_dash.urls' from 'C:\\Users\\DC\\Desktop\\itec320_project20801530\\itec320_project20801530\\itec320_project\\secretary_dash\\urls.py'> (secretary_dash:secretary_dash) ''>, <URLPattern 'patients/add/' [name='patient_create']>], [<URLResolver <module 'secretary_dash.urls' from 'C:\\Users\\DC\\Desktop\\itec320_project20801530\\itec320_project20801530\\itec320_project\\secretary_dash\\urls.py'> (secretary_dash:secretary_dash) ''>, <URLPattern 'patients/<int:pk>/' [name='patient_detail']>], [<URLResolver <module 'secretary_dash.urls' from 'C:\\Users\\DC\\Desktop\\itec320_project20801530\\itec320_project20801530\\itec320_project\\secretary_dash\\urls.py'> (secretary_dash:secretary_dash) ''>, <URLPattern 'patients/<int:pk>/edit/' [name='patient_edit']>], [<URLResolver <module 'secretary_dash.urls' from 'C:\\Users\\DC\\Desktop\\itec320_project20801530\\itec320_project20801530\\itec320_project\\secretary_dash\\urls.py'> (secretary_dash:secretary_dash) ''>, <URLPattern 'patients/<int:pk>/delete/' [name='patient_delete']>], [<URLResolver <module 'secretary_dash.urls' from 'C:\\Users\\DC\\Desktop\\itec320_project20801530\\itec320_project20801530\\itec320_project\\secretary_dash\\urls.py'> (secretary_dash:secretary_dash) ''>, <URLPattern 'appointments/' [name='appointment_list']>], [<URLResolver <module 'secretary_dash.urls' from 'C:\\Users\\DC\\Desktop\\itec320_project20801530\\itec320_project20801530\\itec320_project\\secretary_dash\\urls.py'> (secretary_dash:secretary_dash) ''>, <URLPattern 'appointments/add/' [name='appointment_create']>], [<URLResolver <module 'secretary_dash.urls' from 'C:\\Users\\DC\\Desktop\\itec320_project20801530\\itec320_project20801530\\itec320_project\\secretary_dash\\urls.py'> (secretary_dash:secretary_dash) ''>, <URLPattern 'appointments/<int:pk>/' [name='appointment_detail']>], [<URLResolver <module 'secretary_dash.urls' from 'C:\\Users\\DC\\Desktop\\itec320_project20801530\\itec320_project20801530\\itec320_project\\secretary_dash\\urls.py'> (secretary_dash:secretary_dash) ''>, <URLPattern 'appointments/<int:pk>/edit/' [name='appointment_edit']>], [<URLResolver <module 'secretary_dash.urls' from 'C:\\Users\\DC\\Desktop\\itec320_project20801530\\itec320_project20801530\\itec320_project\\secretary_dash\\urls.py'> (secretary_dash:secretary_dash) ''>, <URLPattern 'appointments/<int:pk>/cancel/' [name='appointment_cancel']>], [<URLResolver <module 'secretary_dash.urls' from 'C:\\Users\\DC\\Desktop\\itec320_project20801530\\itec320_project20801530\\itec320_project\\secretary_dash\\urls.py'> (secretary_dash:secretary_dash) ''>, <URLPattern 'appointments/<int:pk>/delete/' [name='appointment_delete']>], [<URLResolver <module 'secretary_dash.urls' from 'C:\\Users\\DC\\Desktop\\itec320_project20801530\\itec320_project20801530\\itec320_project\\secretary_dash\\urls.py'> (secretary_dash:secretary_dash) ''>, <URLPattern 'medicines/' [name='medicine_list']>], [<URLResolver <module 'secretary_dash.urls' from 'C:\\Users\\DC\\Desktop\\itec320_project20801530\\itec320_project20801530\\itec320_project\\secretary_dash\\urls.py'> (secretary_dash:secretary_dash) ''>, <URLPattern 'medicines/add/' [name='medicine_create']>], [<URLResolver <module 'secretary_dash.urls' from 'C:\\Users\\DC\\Desktop\\itec320_project20801530\\itec320_project20801530\\itec320_project\\secretary_dash\\urls.py'> (secretary_dash:secretary_dash) ''>, <URLPattern 'medicines/<int:pk>/edit/' [name='medicine_edit']>], [<URLResolver <module 'secretary_dash.urls' from 'C:\\Users\\DC\\Desktop\\itec320_project20801530\\itec320_project20801530\\itec320_project\\secretary_dash\\urls.py'> (secretary_dash:secretary_dash) ''>, <URLPattern 'medicines/<int:pk>/delete/' [name='medicine_delete']>], [<URLResolver <module 'secretary_dash.urls' from 'C:\\Users\\DC\\Desktop\\itec320_project20801530\\itec320_project20801530\\itec320_project\\secretary_dash\\urls.py'> (secretary_dash:secretary_dash) ''>, <URLPattern 'examinations/' [name='examination_list']>], [<URLResolver <module 'secretary_dash.urls' from 'C:\\Users\\DC\\Desktop\\itec320_project20801530\\itec320_project20801530\\itec320_project\\secretary_dash\\urls.py'> (secretary_dash:secretary_dash) ''>, <URLPattern 'examinations/add/' [name='examination_create']>], [<URLResolver <module 'secretary_dash.urls' from 'C:\\Users\\DC\\Desktop\\itec320_project20801530\\itec320_project20801530\\itec320_project\\secretary_dash\\urls.py'> (secretary_dash:secretary_dash) ''>, <URLPattern 'examinations/<int:pk>/' [name='examination_detail']>], [<URLResolver <module 'secretary_dash.urls' from 'C:\\Users\\DC\\Desktop\\itec320_project20801530\\itec320_project20801530\\itec320_project\\secretary_dash\\urls.py'> (secretary_dash:secretary_dash) ''>, <URLPattern 'examinations/<int:pk>/edit/' [name='examination_edit']>], [<URLResolver <module 'secretary_dash.urls' from 'C:\\Users\\DC\\Desktop\\itec320_project20801530\\itec320_project20801530\\itec320_project\\secretary_dash\\urls.py'> (secretary_dash:secretary_dash) ''>, <URLPattern 'examinations/<int:pk>/delete/' [name='examination_delete']>], [<URLResolver <module 'secretary_dash.urls' from 'C:\\Users\\DC\\Desktop\\itec320_project20801530\\itec320_project20801530\\itec320_project\\secretary_dash\\urls.py'> (secretary_dash:secretary_dash) ''>, <URLPattern 'secretary/' [name='secretary_dashboard']>], [<URLPattern 'login/' [name='login']>], [<URLPattern 'logout/' [name='logout']>]], 'path': 'favicon.ico'}

During handling of the above exception, another exception occurred:

Traceback (most recent call last):
  File "C:\Python312\Lib\site-packages\django\template\base.py", line 883, in _resolve_lookup
    current = current[bit]
              ~~~~~~~^^^^^
TypeError: 'URLResolver' object is not subscriptable

During handling of the above exception, another exception occurred:

Traceback (most recent call last):
  File "C:\Python312\Lib\site-packages\django\template\base.py", line 893, in _resolve_lookup
    current = getattr(current, bit)
              ^^^^^^^^^^^^^^^^^^^^^
AttributeError: 'URLResolver' object has no attribute 'name'

During handling of the above exception, another exception occurred:

Traceback (most recent call last):
  File "C:\Python312\Lib\site-packages\django\template\base.py", line 899, in _resolve_lookup
    current = current[int(bit)]
                      ^^^^^^^^
ValueError: invalid literal for int() with base 10: 'name'

During handling of the above exception, another exception occurred:

Traceback (most recent call last):
  File "C:\Python312\Lib\site-packages\django\template\base.py", line 906, in _resolve_lookup
    raise VariableDoesNotExist(
django.template.base.VariableDoesNotExist: Failed lookup for key [name] in <URLResolver <URLPattern list> (admin:admin) 'admin/'>
DEBUG 2024-12-23 19:56:43,729 base 15672 6372 Exception while resolving variable 'name' in template 'unknown'.
Traceback (most recent call last):
  File "C:\Python312\Lib\site-packages\django\core\handlers\exception.py", line 55, in inner
    response = get_response(request)
               ^^^^^^^^^^^^^^^^^^^^^
  File "C:\Python312\Lib\site-packages\django\core\handlers\base.py", line 181, in _get_response
    callback, callback_args, callback_kwargs = self.resolve_request(request)
                                               ^^^^^^^^^^^^^^^^^^^^^^^^^^^^^
  File "C:\Python312\Lib\site-packages\django\core\handlers\base.py", line 313, in resolve_request
    resolver_match = resolver.resolve(request.path_info)
                     ^^^^^^^^^^^^^^^^^^^^^^^^^^^^^^^^^^^
  File "C:\Python312\Lib\site-packages\django\urls\resolvers.py", line 705, in resolve
    raise Resolver404({"tried": tried, "path": new_path})
django.urls.exceptions.Resolver404: {'tried': [[<URLResolver <URLPattern list> (admin:admin) 'admin/'>], [<URLResolver <module 'secretary_dash.urls' from 'C:\\Users\\DC\\Desktop\\itec320_project20801530\\itec320_project20801530\\itec320_project\\secretary_dash\\urls.py'> (secretary_dash:secretary_dash) ''>, <URLPattern '' [name='root']>], [<URLResolver <module 'secretary_dash.urls' from 'C:\\Users\\DC\\Desktop\\itec320_project20801530\\itec320_project20801530\\itec320_project\\secretary_dash\\urls.py'> (secretary_dash:secretary_dash) ''>, <URLPattern 'forgot-password/' [name='forgot_password']>], [<URLResolver <module 'secretary_dash.urls' from 'C:\\Users\\DC\\Desktop\\itec320_project20801530\\itec320_project20801530\\itec320_project\\secretary_dash\\urls.py'> (secretary_dash:secretary_dash) ''>, <URLPattern 'reset-password/<str:uidb64>/<str:token>/' [name='reset_password']>], [<URLResolver <module 'secretary_dash.urls' from 'C:\\Users\\DC\\Desktop\\itec320_project20801530\\itec320_project20801530\\itec320_project\\secretary_dash\\urls.py'> (secretary_dash:secretary_dash) ''>, <URLPattern 'doctor/' [name='doctor_dashboard']>], [<URLResolver <module 'secretary_dash.urls' from 'C:\\Users\\DC\\Desktop\\itec320_project20801530\\itec320_project20801530\\itec320_project\\secretary_dash\\urls.py'> (secretary_dash:secretary_dash) ''>, <URLPattern 'doctor/secretaries/' [name='secretary_list']>], [<URLResolver <module 'secretary_dash.urls' from 'C:\\Users\\DC\\Desktop\\itec320_project20801530\\itec320_project20801530\\itec320_project\\secretary_dash\\urls.py'> (secretary_dash:secretary_dash) ''>, <URLPattern 'doctor/secretaries/add/' [name='secretary_create']>], [<URLResolver <module 'secretary_dash.urls' from 'C:\\Users\\DC\\Desktop\\itec320_project20801530\\itec320_project20801530\\itec320_project\\secretary_dash\\urls.py'> (secretary_dash:secretary_dash) ''>, <URLPattern 'doctor/secretaries/<int:pk>/edit/' [name='secretary_edit']>], [<URLResolver <module 'secretary_dash.urls' from 'C:\\Users\\DC\\Desktop\\itec320_project20801530\\itec320_project20801530\\itec320_project\\secretary_dash\\urls.py'> (secretary_dash:secretary_dash) ''>, <URLPattern 'doctor/secretaries/<int:pk>/delete/' [name='secretary_delete']>], [<URLResolver <module 'secretary_dash.urls' from 'C:\\Users\\DC\\Desktop\\itec320_project20801530\\itec320_project20801530\\itec320_project\\secretary_dash\\urls.py'> (secretary_dash:secretary_dash) ''>, <URLPattern 'doctor/busy-hours/' [name='busy_hours_list']>], [<URLResolver <module 'secretary_dash.urls' from 'C:\\Users\\DC\\Desktop\\itec320_project20801530\\itec320_project20801530\\itec320_project\\secretary_dash\\urls.py'> (secretary_dash:secretary_dash) ''>, <URLPattern 'doctor/busy-hours/add/' [name='busy_hours_create']>], [<URLResolver <module 'secretary_dash.urls' from 'C:\\Users\\DC\\Desktop\\itec320_project20801530\\itec320_project20801530\\itec320_project\\secretary_dash\\urls.py'> (secretary_dash:secretary_dash) ''>, <URLPattern 'doctor/busy-hours/<int:pk>/edit/' [name='busy_hours_edit']>], [<URLResolver <module 'secretary_dash.urls' from 'C:\\Users\\DC\\Desktop\\itec320_project20801530\\itec320_project20801530\\itec320_project\\secretary_dash\\urls.py'> (secretary_dash:secretary_dash) ''>, <URLPattern 'doctor/busy-hours/<int:pk>/delete/' [name='busy_hours_delete']>], [<URLResolver <module 'secretary_dash.urls' from 'C:\\Users\\DC\\Desktop\\itec320_project20801530\\itec320_project20801530\\itec320_project\\secretary_dash\\urls.py'> (secretary_dash:secretary_dash) ''>, <URLPattern 'patients/' [name='patient_list']>], [<URLResolver <module 'secretary_dash.urls' from 'C:\\Users\\DC\\Desktop\\itec320_project20801530\\itec320_project20801530\\itec320_project\\secretary_dash\\urls.py'> (secretary_dash:secretary_dash) ''>, <URLPattern 'patients/add/' [name='patient_create']>], [<URLResolver <module 'secretary_dash.urls' from 'C:\\Users\\DC\\Desktop\\itec320_project20801530\\itec320_project20801530\\itec320_project\\secretary_dash\\urls.py'> (secretary_dash:secretary_dash) ''>, <URLPattern 'patients/<int:pk>/' [name='patient_detail']>], [<URLResolver <module 'secretary_dash.urls' from 'C:\\Users\\DC\\Desktop\\itec320_project20801530\\itec320_project20801530\\itec320_project\\secretary_dash\\urls.py'> (secretary_dash:secretary_dash) ''>, <URLPattern 'patients/<int:pk>/edit/' [name='patient_edit']>], [<URLResolver <module 'secretary_dash.urls' from 'C:\\Users\\DC\\Desktop\\itec320_project20801530\\itec320_project20801530\\itec320_project\\secretary_dash\\urls.py'> (secretary_dash:secretary_dash) ''>, <URLPattern 'patients/<int:pk>/delete/' [name='patient_delete']>], [<URLResolver <module 'secretary_dash.urls' from 'C:\\Users\\DC\\Desktop\\itec320_project20801530\\itec320_project20801530\\itec320_project\\secretary_dash\\urls.py'> (secretary_dash:secretary_dash) ''>, <URLPattern 'appointments/' [name='appointment_list']>], [<URLResolver <module 'secretary_dash.urls' from 'C:\\Users\\DC\\Desktop\\itec320_project20801530\\itec320_project20801530\\itec320_project\\secretary_dash\\urls.py'> (secretary_dash:secretary_dash) ''>, <URLPattern 'appointments/add/' [name='appointment_create']>], [<URLResolver <module 'secretary_dash.urls' from 'C:\\Users\\DC\\Desktop\\itec320_project20801530\\itec320_project20801530\\itec320_project\\secretary_dash\\urls.py'> (secretary_dash:secretary_dash) ''>, <URLPattern 'appointments/<int:pk>/' [name='appointment_detail']>], [<URLResolver <module 'secretary_dash.urls' from 'C:\\Users\\DC\\Desktop\\itec320_project20801530\\itec320_project20801530\\itec320_project\\secretary_dash\\urls.py'> (secretary_dash:secretary_dash) ''>, <URLPattern 'appointments/<int:pk>/edit/' [name='appointment_edit']>], [<URLResolver <module 'secretary_dash.urls' from 'C:\\Users\\DC\\Desktop\\itec320_project20801530\\itec320_project20801530\\itec320_project\\secretary_dash\\urls.py'> (secretary_dash:secretary_dash) ''>, <URLPattern 'appointments/<int:pk>/cancel/' [name='appointment_cancel']>], [<URLResolver <module 'secretary_dash.urls' from 'C:\\Users\\DC\\Desktop\\itec320_project20801530\\itec320_project20801530\\itec320_project\\secretary_dash\\urls.py'> (secretary_dash:secretary_dash) ''>, <URLPattern 'appointments/<int:pk>/delete/' [name='appointment_delete']>], [<URLResolver <module 'secretary_dash.urls' from 'C:\\Users\\DC\\Desktop\\itec320_project20801530\\itec320_project20801530\\itec320_project\\secretary_dash\\urls.py'> (secretary_dash:secretary_dash) ''>, <URLPattern 'medicines/' [name='medicine_list']>], [<URLResolver <module 'secretary_dash.urls' from 'C:\\Users\\DC\\Desktop\\itec320_project20801530\\itec320_project20801530\\itec320_project\\secretary_dash\\urls.py'> (secretary_dash:secretary_dash) ''>, <URLPattern 'medicines/add/' [name='medicine_create']>], [<URLResolver <module 'secretary_dash.urls' from 'C:\\Users\\DC\\Desktop\\itec320_project20801530\\itec320_project20801530\\itec320_project\\secretary_dash\\urls.py'> (secretary_dash:secretary_dash) ''>, <URLPattern 'medicines/<int:pk>/edit/' [name='medicine_edit']>], [<URLResolver <module 'secretary_dash.urls' from 'C:\\Users\\DC\\Desktop\\itec320_project20801530\\itec320_project20801530\\itec320_project\\secretary_dash\\urls.py'> (secretary_dash:secretary_dash) ''>, <URLPattern 'medicines/<int:pk>/delete/' [name='medicine_delete']>], [<URLResolver <module 'secretary_dash.urls' from 'C:\\Users\\DC\\Desktop\\itec320_project20801530\\itec320_project20801530\\itec320_project\\secretary_dash\\urls.py'> (secretary_dash:secretary_dash) ''>, <URLPattern 'examinations/' [name='examination_list']>], [<URLResolver <module 'secretary_dash.urls' from 'C:\\Users\\DC\\Desktop\\itec320_project20801530\\itec320_project20801530\\itec320_project\\secretary_dash\\urls.py'> (secretary_dash:secretary_dash) ''>, <URLPattern 'examinations/add/' [name='examination_create']>], [<URLResolver <module 'secretary_dash.urls' from 'C:\\Users\\DC\\Desktop\\itec320_project20801530\\itec320_project20801530\\itec320_project\\secretary_dash\\urls.py'> (secretary_dash:secretary_dash) ''>, <URLPattern 'examinations/<int:pk>/' [name='examination_detail']>], [<URLResolver <module 'secretary_dash.urls' from 'C:\\Users\\DC\\Desktop\\itec320_project20801530\\itec320_project20801530\\itec320_project\\secretary_dash\\urls.py'> (secretary_dash:secretary_dash) ''>, <URLPattern 'examinations/<int:pk>/edit/' [name='examination_edit']>], [<URLResolver <module 'secretary_dash.urls' from 'C:\\Users\\DC\\Desktop\\itec320_project20801530\\itec320_project20801530\\itec320_project\\secretary_dash\\urls.py'> (secretary_dash:secretary_dash) ''>, <URLPattern 'examinations/<int:pk>/delete/' [name='examination_delete']>], [<URLResolver <module 'secretary_dash.urls' from 'C:\\Users\\DC\\Desktop\\itec320_project20801530\\itec320_project20801530\\itec320_project\\secretary_dash\\urls.py'> (secretary_dash:secretary_dash) ''>, <URLPattern 'secretary/' [name='secretary_dashboard']>], [<URLPattern 'login/' [name='login']>], [<URLPattern 'logout/' [name='logout']>]], 'path': 'favicon.ico'}

During handling of the above exception, another exception occurred:

Traceback (most recent call last):
  File "C:\Python312\Lib\site-packages\django\template\base.py", line 883, in _resolve_lookup
    current = current[bit]
              ~~~~~~~^^^^^
TypeError: 'URLResolver' object is not subscriptable

During handling of the above exception, another exception occurred:

Traceback (most recent call last):
  File "C:\Python312\Lib\site-packages\django\template\base.py", line 893, in _resolve_lookup
    current = getattr(current, bit)
              ^^^^^^^^^^^^^^^^^^^^^
AttributeError: 'URLResolver' object has no attribute 'name'

During handling of the above exception, another exception occurred:

Traceback (most recent call last):
  File "C:\Python312\Lib\site-packages\django\template\base.py", line 899, in _resolve_lookup
    current = current[int(bit)]
                      ^^^^^^^^
ValueError: invalid literal for int() with base 10: 'name'

During handling of the above exception, another exception occurred:

Traceback (most recent call last):
  File "C:\Python312\Lib\site-packages\django\template\base.py", line 906, in _resolve_lookup
    raise VariableDoesNotExist(
django.template.base.VariableDoesNotExist: Failed lookup for key [name] in <URLResolver <URLPattern list> (admin:admin) 'admin/'>
WARNING 2024-12-23 19:56:43,797 log 15672 6372 Not Found: /favicon.ico
WARNING 2024-12-23 19:56:43,797 basehttp 15672 6372 "GET /favicon.ico HTTP/1.1" 404 11839
INFO 2024-12-23 19:56:54,720 basehttp 15672 4972 "POST /login/ HTTP/1.1" 302 0
INFO 2024-12-23 19:56:54,729 basehttp 15672 4972 "GET / HTTP/1.1" 302 0
INFO 2024-12-23 19:56:54,783 basehttp 15672 4972 "GET /secretary/ HTTP/1.1" 200 27462
INFO 2024-12-23 19:57:11,251 basehttp 15672 4972 "GET /patients/ HTTP/1.1" 200 10739
INFO 2024-12-23 19:57:17,097 basehttp 15672 4972 "GET /appointments/ HTTP/1.1" 200 11984
INFO 2024-12-23 19:58:23,935 basehttp 15672 4972 "GET /appointments/ HTTP/1.1" 200 11760
INFO 2024-12-23 19:58:30,280 basehttp 15672 4972 "POST /logout/ HTTP/1.1" 302 0
INFO 2024-12-23 19:58:30,284 basehttp 15672 4972 "GET /login/ HTTP/1.1" 200 4979
INFO 2024-12-23 19:58:36,397 basehttp 15672 4972 "POST /login/ HTTP/1.1" 302 0
INFO 2024-12-23 19:58:36,405 basehttp 15672 4972 "GET / HTTP/1.1" 302 0
DEBUG 2024-12-23 19:58:36,427 base 15672 4972 Exception while resolving variable 'reason' in template 'secretary_dash/doctor/dashboard.html'.
Traceback (most recent call last):
  File "C:\Python312\Lib\site-packages\django\template\base.py", line 883, in _resolve_lookup
    current = current[bit]
              ~~~~~~~^^^^^
TypeError: 'Appointment' object is not subscriptable

During handling of the above exception, another exception occurred:

Traceback (most recent call last):
  File "C:\Python312\Lib\site-packages\django\template\base.py", line 893, in _resolve_lookup
    current = getattr(current, bit)
              ^^^^^^^^^^^^^^^^^^^^^
AttributeError: 'Appointment' object has no attribute 'reason'

During handling of the above exception, another exception occurred:

Traceback (most recent call last):
  File "C:\Python312\Lib\site-packages\django\template\base.py", line 899, in _resolve_lookup
    current = current[int(bit)]
                      ^^^^^^^^
ValueError: invalid literal for int() with base 10: 'reason'

During handling of the above exception, another exception occurred:

Traceback (most recent call last):
  File "C:\Python312\Lib\site-packages\django\template\base.py", line 906, in _resolve_lookup
    raise VariableDoesNotExist(
django.template.base.VariableDoesNotExist: Failed lookup for key [reason] in <Appointment: Sickly De Santos - 2024-12-23 09:00>
DEBUG 2024-12-23 19:58:36,427 base 15672 4972 Exception while resolving variable 'reason' in template 'secretary_dash/doctor/dashboard.html'.
Traceback (most recent call last):
  File "C:\Python312\Lib\site-packages\django\template\base.py", line 883, in _resolve_lookup
    current = current[bit]
              ~~~~~~~^^^^^
TypeError: 'Appointment' object is not subscriptable

During handling of the above exception, another exception occurred:

Traceback (most recent call last):
  File "C:\Python312\Lib\site-packages\django\template\base.py", line 893, in _resolve_lookup
    current = getattr(current, bit)
              ^^^^^^^^^^^^^^^^^^^^^
AttributeError: 'Appointment' object has no attribute 'reason'

During handling of the above exception, another exception occurred:

Traceback (most recent call last):
  File "C:\Python312\Lib\site-packages\django\template\base.py", line 899, in _resolve_lookup
    current = current[int(bit)]
                      ^^^^^^^^
ValueError: invalid literal for int() with base 10: 'reason'

During handling of the above exception, another exception occurred:

Traceback (most recent call last):
  File "C:\Python312\Lib\site-packages\django\template\base.py", line 906, in _resolve_lookup
    raise VariableDoesNotExist(
django.template.base.VariableDoesNotExist: Failed lookup for key [reason] in <Appointment: Sickly De Santos - 2024-12-23 09:00>
DEBUG 2024-12-23 19:58:36,429 base 15672 4972 Exception while resolving variable 'reason' in template 'secretary_dash/doctor/dashboard.html'.
Traceback (most recent call last):
  File "C:\Python312\Lib\site-packages\django\template\base.py", line 883, in _resolve_lookup
    current = current[bit]
              ~~~~~~~^^^^^
TypeError: 'Appointment' object is not subscriptable

During handling of the above exception, another exception occurred:

Traceback (most recent call last):
  File "C:\Python312\Lib\site-packages\django\template\base.py", line 893, in _resolve_lookup
    current = getattr(current, bit)
              ^^^^^^^^^^^^^^^^^^^^^
AttributeError: 'Appointment' object has no attribute 'reason'

During handling of the above exception, another exception occurred:

Traceback (most recent call last):
  File "C:\Python312\Lib\site-packages\django\template\base.py", line 899, in _resolve_lookup
    current = current[int(bit)]
                      ^^^^^^^^
ValueError: invalid literal for int() with base 10: 'reason'

During handling of the above exception, another exception occurred:

Traceback (most recent call last):
  File "C:\Python312\Lib\site-packages\django\template\base.py", line 906, in _resolve_lookup
    raise VariableDoesNotExist(
django.template.base.VariableDoesNotExist: Failed lookup for key [reason] in <Appointment: John doe - 2024-12-23 10:30>
DEBUG 2024-12-23 19:58:36,429 base 15672 4972 Exception while resolving variable 'reason' in template 'secretary_dash/doctor/dashboard.html'.
Traceback (most recent call last):
  File "C:\Python312\Lib\site-packages\django\template\base.py", line 883, in _resolve_lookup
    current = current[bit]
              ~~~~~~~^^^^^
TypeError: 'Appointment' object is not subscriptable

During handling of the above exception, another exception occurred:

Traceback (most recent call last):
  File "C:\Python312\Lib\site-packages\django\template\base.py", line 893, in _resolve_lookup
    current = getattr(current, bit)
              ^^^^^^^^^^^^^^^^^^^^^
AttributeError: 'Appointment' object has no attribute 'reason'

During handling of the above exception, another exception occurred:

Traceback (most recent call last):
  File "C:\Python312\Lib\site-packages\django\template\base.py", line 899, in _resolve_lookup
    current = current[int(bit)]
                      ^^^^^^^^
ValueError: invalid literal for int() with base 10: 'reason'

During handling of the above exception, another exception occurred:

Traceback (most recent call last):
  File "C:\Python312\Lib\site-packages\django\template\base.py", line 906, in _resolve_lookup
    raise VariableDoesNotExist(
django.template.base.VariableDoesNotExist: Failed lookup for key [reason] in <Appointment: John doe - 2024-12-23 10:30>
DEBUG 2024-12-23 19:58:36,432 base 15672 4972 Exception while resolving variable 'reason' in template 'secretary_dash/doctor/dashboard.html'.
Traceback (most recent call last):
  File "C:\Python312\Lib\site-packages\django\template\base.py", line 883, in _resolve_lookup
    current = current[bit]
              ~~~~~~~^^^^^
TypeError: 'Appointment' object is not subscriptable

During handling of the above exception, another exception occurred:

Traceback (most recent call last):
  File "C:\Python312\Lib\site-packages\django\template\base.py", line 893, in _resolve_lookup
    current = getattr(current, bit)
              ^^^^^^^^^^^^^^^^^^^^^
AttributeError: 'Appointment' object has no attribute 'reason'

During handling of the above exception, another exception occurred:

Traceback (most recent call last):
  File "C:\Python312\Lib\site-packages\django\template\base.py", line 899, in _resolve_lookup
    current = current[int(bit)]
                      ^^^^^^^^
ValueError: invalid literal for int() with base 10: 'reason'

During handling of the above exception, another exception occurred:

Traceback (most recent call last):
  File "C:\Python312\Lib\site-packages\django\template\base.py", line 906, in _resolve_lookup
    raise VariableDoesNotExist(
django.template.base.VariableDoesNotExist: Failed lookup for key [reason] in <Appointment: psyc D. mann - 2024-12-23 12:00>
DEBUG 2024-12-23 19:58:36,432 base 15672 4972 Exception while resolving variable 'reason' in template 'secretary_dash/doctor/dashboard.html'.
Traceback (most recent call last):
  File "C:\Python312\Lib\site-packages\django\template\base.py", line 883, in _resolve_lookup
    current = current[bit]
              ~~~~~~~^^^^^
TypeError: 'Appointment' object is not subscriptable

During handling of the above exception, another exception occurred:

Traceback (most recent call last):
  File "C:\Python312\Lib\site-packages\django\template\base.py", line 893, in _resolve_lookup
    current = getattr(current, bit)
              ^^^^^^^^^^^^^^^^^^^^^
AttributeError: 'Appointment' object has no attribute 'reason'

During handling of the above exception, another exception occurred:

Traceback (most recent call last):
  File "C:\Python312\Lib\site-packages\django\template\base.py", line 899, in _resolve_lookup
    current = current[int(bit)]
                      ^^^^^^^^
ValueError: invalid literal for int() with base 10: 'reason'

During handling of the above exception, another exception occurred:

Traceback (most recent call last):
  File "C:\Python312\Lib\site-packages\django\template\base.py", line 906, in _resolve_lookup
    raise VariableDoesNotExist(
django.template.base.VariableDoesNotExist: Failed lookup for key [reason] in <Appointment: psyc D. mann - 2024-12-23 12:00>
DEBUG 2024-12-23 19:58:36,434 base 15672 4972 Exception while resolving variable 'reason' in template 'secretary_dash/doctor/dashboard.html'.
Traceback (most recent call last):
  File "C:\Python312\Lib\site-packages\django\template\base.py", line 883, in _resolve_lookup
    current = current[bit]
              ~~~~~~~^^^^^
TypeError: 'Appointment' object is not subscriptable

During handling of the above exception, another exception occurred:

Traceback (most recent call last):
  File "C:\Python312\Lib\site-packages\django\template\base.py", line 893, in _resolve_lookup
    current = getattr(current, bit)
              ^^^^^^^^^^^^^^^^^^^^^
AttributeError: 'Appointment' object has no attribute 'reason'

During handling of the above exception, another exception occurred:

Traceback (most recent call last):
  File "C:\Python312\Lib\site-packages\django\template\base.py", line 899, in _resolve_lookup
    current = current[int(bit)]
                      ^^^^^^^^
ValueError: invalid literal for int() with base 10: 'reason'

During handling of the above exception, another exception occurred:

Traceback (most recent call last):
  File "C:\Python312\Lib\site-packages\django\template\base.py", line 906, in _resolve_lookup
    raise VariableDoesNotExist(
django.template.base.VariableDoesNotExist: Failed lookup for key [reason] in <Appointment: psyc D. mann - 2024-12-23 14:00>
DEBUG 2024-12-23 19:58:36,434 base 15672 4972 Exception while resolving variable 'reason' in template 'secretary_dash/doctor/dashboard.html'.
Traceback (most recent call last):
  File "C:\Python312\Lib\site-packages\django\template\base.py", line 883, in _resolve_lookup
    current = current[bit]
              ~~~~~~~^^^^^
TypeError: 'Appointment' object is not subscriptable

During handling of the above exception, another exception occurred:

Traceback (most recent call last):
  File "C:\Python312\Lib\site-packages\django\template\base.py", line 893, in _resolve_lookup
    current = getattr(current, bit)
              ^^^^^^^^^^^^^^^^^^^^^
AttributeError: 'Appointment' object has no attribute 'reason'

During handling of the above exception, another exception occurred:

Traceback (most recent call last):
  File "C:\Python312\Lib\site-packages\django\template\base.py", line 899, in _resolve_lookup
    current = current[int(bit)]
                      ^^^^^^^^
ValueError: invalid literal for int() with base 10: 'reason'

During handling of the above exception, another exception occurred:

Traceback (most recent call last):
  File "C:\Python312\Lib\site-packages\django\template\base.py", line 906, in _resolve_lookup
    raise VariableDoesNotExist(
django.template.base.VariableDoesNotExist: Failed lookup for key [reason] in <Appointment: psyc D. mann - 2024-12-23 14:00>
DEBUG 2024-12-23 19:58:36,437 base 15672 4972 Exception while resolving variable 'reason' in template 'secretary_dash/doctor/dashboard.html'.
Traceback (most recent call last):
  File "C:\Python312\Lib\site-packages\django\template\base.py", line 883, in _resolve_lookup
    current = current[bit]
              ~~~~~~~^^^^^
TypeError: 'Appointment' object is not subscriptable

During handling of the above exception, another exception occurred:

Traceback (most recent call last):
  File "C:\Python312\Lib\site-packages\django\template\base.py", line 893, in _resolve_lookup
    current = getattr(current, bit)
              ^^^^^^^^^^^^^^^^^^^^^
AttributeError: 'Appointment' object has no attribute 'reason'

During handling of the above exception, another exception occurred:

Traceback (most recent call last):
  File "C:\Python312\Lib\site-packages\django\template\base.py", line 899, in _resolve_lookup
    current = current[int(bit)]
                      ^^^^^^^^
ValueError: invalid literal for int() with base 10: 'reason'

During handling of the above exception, another exception occurred:

Traceback (most recent call last):
  File "C:\Python312\Lib\site-packages\django\template\base.py", line 906, in _resolve_lookup
    raise VariableDoesNotExist(
django.template.base.VariableDoesNotExist: Failed lookup for key [reason] in <Appointment: Corey V. Depen - 2024-12-23 16:00>
DEBUG 2024-12-23 19:58:36,437 base 15672 4972 Exception while resolving variable 'reason' in template 'secretary_dash/doctor/dashboard.html'.
Traceback (most recent call last):
  File "C:\Python312\Lib\site-packages\django\template\base.py", line 883, in _resolve_lookup
    current = current[bit]
              ~~~~~~~^^^^^
TypeError: 'Appointment' object is not subscriptable

During handling of the above exception, another exception occurred:

Traceback (most recent call last):
  File "C:\Python312\Lib\site-packages\django\template\base.py", line 893, in _resolve_lookup
    current = getattr(current, bit)
              ^^^^^^^^^^^^^^^^^^^^^
AttributeError: 'Appointment' object has no attribute 'reason'

During handling of the above exception, another exception occurred:

Traceback (most recent call last):
  File "C:\Python312\Lib\site-packages\django\template\base.py", line 899, in _resolve_lookup
    current = current[int(bit)]
                      ^^^^^^^^
ValueError: invalid literal for int() with base 10: 'reason'

During handling of the above exception, another exception occurred:

Traceback (most recent call last):
  File "C:\Python312\Lib\site-packages\django\template\base.py", line 906, in _resolve_lookup
    raise VariableDoesNotExist(
django.template.base.VariableDoesNotExist: Failed lookup for key [reason] in <Appointment: Corey V. Depen - 2024-12-23 16:00>
INFO 2024-12-23 19:58:36,441 basehttp 15672 4972 "GET /doctor/ HTTP/1.1" 200 33508
INFO 2024-12-23 19:58:55,514 basehttp 15672 4972 "GET /doctor/secretaries/ HTTP/1.1" 200 7603
INFO 2024-12-23 19:58:58,178 basehttp 15672 4972 "GET /patients/ HTTP/1.1" 200 11564
INFO 2024-12-23 19:59:01,361 basehttp 15672 4972 "GET /medicines/ HTTP/1.1" 200 8526
INFO 2024-12-23 19:59:06,070 basehttp 15672 4972 "GET /appointments/ HTTP/1.1" 200 12867
INFO 2024-12-23 19:59:08,606 basehttp 15672 4972 "GET /examinations/add/?appointment=6 HTTP/1.1" 200 12059
DEBUG 2024-12-23 19:59:10,651 base 15672 4972 Exception while resolving variable 'is_completed' in template 'secretary_dash/doctor/examination_list.html'.
Traceback (most recent call last):
  File "C:\Python312\Lib\site-packages\django\template\base.py", line 883, in _resolve_lookup
    current = current[bit]
              ~~~~~~~^^^^^
TypeError: 'Examination' object is not subscriptable

During handling of the above exception, another exception occurred:

Traceback (most recent call last):
  File "C:\Python312\Lib\site-packages\django\template\base.py", line 893, in _resolve_lookup
    current = getattr(current, bit)
              ^^^^^^^^^^^^^^^^^^^^^
AttributeError: 'Examination' object has no attribute 'is_completed'

During handling of the above exception, another exception occurred:

Traceback (most recent call last):
  File "C:\Python312\Lib\site-packages\django\template\base.py", line 899, in _resolve_lookup
    current = current[int(bit)]
                      ^^^^^^^^
ValueError: invalid literal for int() with base 10: 'is_completed'

During handling of the above exception, another exception occurred:

Traceback (most recent call last):
  File "C:\Python312\Lib\site-packages\django\template\base.py", line 906, in _resolve_lookup
    raise VariableDoesNotExist(
django.template.base.VariableDoesNotExist: Failed lookup for key [is_completed] in <Examination: Examination for psyc D. mann on 2024-12-23>
DEBUG 2024-12-23 19:59:10,651 base 15672 4972 Exception while resolving variable 'is_completed' in template 'secretary_dash/doctor/examination_list.html'.
Traceback (most recent call last):
  File "C:\Python312\Lib\site-packages\django\template\base.py", line 883, in _resolve_lookup
    current = current[bit]
              ~~~~~~~^^^^^
TypeError: 'Examination' object is not subscriptable

During handling of the above exception, another exception occurred:

Traceback (most recent call last):
  File "C:\Python312\Lib\site-packages\django\template\base.py", line 893, in _resolve_lookup
    current = getattr(current, bit)
              ^^^^^^^^^^^^^^^^^^^^^
AttributeError: 'Examination' object has no attribute 'is_completed'

During handling of the above exception, another exception occurred:

Traceback (most recent call last):
  File "C:\Python312\Lib\site-packages\django\template\base.py", line 899, in _resolve_lookup
    current = current[int(bit)]
                      ^^^^^^^^
ValueError: invalid literal for int() with base 10: 'is_completed'

During handling of the above exception, another exception occurred:

Traceback (most recent call last):
  File "C:\Python312\Lib\site-packages\django\template\base.py", line 906, in _resolve_lookup
    raise VariableDoesNotExist(
django.template.base.VariableDoesNotExist: Failed lookup for key [is_completed] in <Examination: Examination for psyc D. mann on 2024-12-23>
DEBUG 2024-12-23 19:59:10,658 base 15672 4972 Exception while resolving variable 'is_completed' in template 'secretary_dash/doctor/examination_list.html'.
Traceback (most recent call last):
  File "C:\Python312\Lib\site-packages\django\template\base.py", line 883, in _resolve_lookup
    current = current[bit]
              ~~~~~~~^^^^^
TypeError: 'Examination' object is not subscriptable

During handling of the above exception, another exception occurred:

Traceback (most recent call last):
  File "C:\Python312\Lib\site-packages\django\template\base.py", line 893, in _resolve_lookup
    current = getattr(current, bit)
              ^^^^^^^^^^^^^^^^^^^^^
AttributeError: 'Examination' object has no attribute 'is_completed'

During handling of the above exception, another exception occurred:

Traceback (most recent call last):
  File "C:\Python312\Lib\site-packages\django\template\base.py", line 899, in _resolve_lookup
    current = current[int(bit)]
                      ^^^^^^^^
ValueError: invalid literal for int() with base 10: 'is_completed'

During handling of the above exception, another exception occurred:

Traceback (most recent call last):
  File "C:\Python312\Lib\site-packages\django\template\base.py", line 906, in _resolve_lookup
    raise VariableDoesNotExist(
django.template.base.VariableDoesNotExist: Failed lookup for key [is_completed] in <Examination: Examination for Sickly De Santos on 2024-12-23>
DEBUG 2024-12-23 19:59:10,658 base 15672 4972 Exception while resolving variable 'is_completed' in template 'secretary_dash/doctor/examination_list.html'.
Traceback (most recent call last):
  File "C:\Python312\Lib\site-packages\django\template\base.py", line 883, in _resolve_lookup
    current = current[bit]
              ~~~~~~~^^^^^
TypeError: 'Examination' object is not subscriptable

During handling of the above exception, another exception occurred:

Traceback (most recent call last):
  File "C:\Python312\Lib\site-packages\django\template\base.py", line 893, in _resolve_lookup
    current = getattr(current, bit)
              ^^^^^^^^^^^^^^^^^^^^^
AttributeError: 'Examination' object has no attribute 'is_completed'

During handling of the above exception, another exception occurred:

Traceback (most recent call last):
  File "C:\Python312\Lib\site-packages\django\template\base.py", line 899, in _resolve_lookup
    current = current[int(bit)]
                      ^^^^^^^^
ValueError: invalid literal for int() with base 10: 'is_completed'

During handling of the above exception, another exception occurred:

Traceback (most recent call last):
  File "C:\Python312\Lib\site-packages\django\template\base.py", line 906, in _resolve_lookup
    raise VariableDoesNotExist(
django.template.base.VariableDoesNotExist: Failed lookup for key [is_completed] in <Examination: Examination for Sickly De Santos on 2024-12-23>
DEBUG 2024-12-23 19:59:10,662 base 15672 4972 Exception while resolving variable 'is_completed' in template 'secretary_dash/doctor/examination_list.html'.
Traceback (most recent call last):
  File "C:\Python312\Lib\site-packages\django\template\base.py", line 883, in _resolve_lookup
    current = current[bit]
              ~~~~~~~^^^^^
TypeError: 'Examination' object is not subscriptable

During handling of the above exception, another exception occurred:

Traceback (most recent call last):
  File "C:\Python312\Lib\site-packages\django\template\base.py", line 893, in _resolve_lookup
    current = getattr(current, bit)
              ^^^^^^^^^^^^^^^^^^^^^
AttributeError: 'Examination' object has no attribute 'is_completed'

During handling of the above exception, another exception occurred:

Traceback (most recent call last):
  File "C:\Python312\Lib\site-packages\django\template\base.py", line 899, in _resolve_lookup
    current = current[int(bit)]
                      ^^^^^^^^
ValueError: invalid literal for int() with base 10: 'is_completed'

During handling of the above exception, another exception occurred:

Traceback (most recent call last):
  File "C:\Python312\Lib\site-packages\django\template\base.py", line 906, in _resolve_lookup
    raise VariableDoesNotExist(
django.template.base.VariableDoesNotExist: Failed lookup for key [is_completed] in <Examination: Examination for John doe on 2024-12-23>
DEBUG 2024-12-23 19:59:10,662 base 15672 4972 Exception while resolving variable 'is_completed' in template 'secretary_dash/doctor/examination_list.html'.
Traceback (most recent call last):
  File "C:\Python312\Lib\site-packages\django\template\base.py", line 883, in _resolve_lookup
    current = current[bit]
              ~~~~~~~^^^^^
TypeError: 'Examination' object is not subscriptable

During handling of the above exception, another exception occurred:

Traceback (most recent call last):
  File "C:\Python312\Lib\site-packages\django\template\base.py", line 893, in _resolve_lookup
    current = getattr(current, bit)
              ^^^^^^^^^^^^^^^^^^^^^
AttributeError: 'Examination' object has no attribute 'is_completed'

During handling of the above exception, another exception occurred:

Traceback (most recent call last):
  File "C:\Python312\Lib\site-packages\django\template\base.py", line 899, in _resolve_lookup
    current = current[int(bit)]
                      ^^^^^^^^
ValueError: invalid literal for int() with base 10: 'is_completed'

During handling of the above exception, another exception occurred:

Traceback (most recent call last):
  File "C:\Python312\Lib\site-packages\django\template\base.py", line 906, in _resolve_lookup
    raise VariableDoesNotExist(
django.template.base.VariableDoesNotExist: Failed lookup for key [is_completed] in <Examination: Examination for John doe on 2024-12-23>
DEBUG 2024-12-23 19:59:10,668 base 15672 4972 Exception while resolving variable 'is_completed' in template 'secretary_dash/doctor/examination_list.html'.
Traceback (most recent call last):
  File "C:\Python312\Lib\site-packages\django\template\base.py", line 883, in _resolve_lookup
    current = current[bit]
              ~~~~~~~^^^^^
TypeError: 'Examination' object is not subscriptable

During handling of the above exception, another exception occurred:

Traceback (most recent call last):
  File "C:\Python312\Lib\site-packages\django\template\base.py", line 893, in _resolve_lookup
    current = getattr(current, bit)
              ^^^^^^^^^^^^^^^^^^^^^
AttributeError: 'Examination' object has no attribute 'is_completed'

During handling of the above exception, another exception occurred:

Traceback (most recent call last):
  File "C:\Python312\Lib\site-packages\django\template\base.py", line 899, in _resolve_lookup
    current = current[int(bit)]
                      ^^^^^^^^
ValueError: invalid literal for int() with base 10: 'is_completed'

During handling of the above exception, another exception occurred:

Traceback (most recent call last):
  File "C:\Python312\Lib\site-packages\django\template\base.py", line 906, in _resolve_lookup
    raise VariableDoesNotExist(
django.template.base.VariableDoesNotExist: Failed lookup for key [is_completed] in <Examination: Examination for psyc D. mann on 2024-12-22>
DEBUG 2024-12-23 19:59:10,668 base 15672 4972 Exception while resolving variable 'is_completed' in template 'secretary_dash/doctor/examination_list.html'.
Traceback (most recent call last):
  File "C:\Python312\Lib\site-packages\django\template\base.py", line 883, in _resolve_lookup
    current = current[bit]
              ~~~~~~~^^^^^
TypeError: 'Examination' object is not subscriptable

During handling of the above exception, another exception occurred:

Traceback (most recent call last):
  File "C:\Python312\Lib\site-packages\django\template\base.py", line 893, in _resolve_lookup
    current = getattr(current, bit)
              ^^^^^^^^^^^^^^^^^^^^^
AttributeError: 'Examination' object has no attribute 'is_completed'

During handling of the above exception, another exception occurred:

Traceback (most recent call last):
  File "C:\Python312\Lib\site-packages\django\template\base.py", line 899, in _resolve_lookup
    current = current[int(bit)]
                      ^^^^^^^^
ValueError: invalid literal for int() with base 10: 'is_completed'

During handling of the above exception, another exception occurred:

Traceback (most recent call last):
  File "C:\Python312\Lib\site-packages\django\template\base.py", line 906, in _resolve_lookup
    raise VariableDoesNotExist(
django.template.base.VariableDoesNotExist: Failed lookup for key [is_completed] in <Examination: Examination for psyc D. mann on 2024-12-22>
INFO 2024-12-23 19:59:10,673 basehttp 15672 4972 "GET /examinations/ HTTP/1.1" 200 11570
INFO 2024-12-23 19:59:15,094 basehttp 15672 4972 "GET /appointments/ HTTP/1.1" 200 12867
DEBUG 2024-12-23 19:59:21,320 base 15672 4972 Exception while resolving variable 'is_completed' in template 'secretary_dash/doctor/examination_list.html'.
Traceback (most recent call last):
  File "C:\Python312\Lib\site-packages\django\template\base.py", line 883, in _resolve_lookup
    current = current[bit]
              ~~~~~~~^^^^^
TypeError: 'Examination' object is not subscriptable

During handling of the above exception, another exception occurred:

Traceback (most recent call last):
  File "C:\Python312\Lib\site-packages\django\template\base.py", line 893, in _resolve_lookup
    current = getattr(current, bit)
              ^^^^^^^^^^^^^^^^^^^^^
AttributeError: 'Examination' object has no attribute 'is_completed'

During handling of the above exception, another exception occurred:

Traceback (most recent call last):
  File "C:\Python312\Lib\site-packages\django\template\base.py", line 899, in _resolve_lookup
    current = current[int(bit)]
                      ^^^^^^^^
ValueError: invalid literal for int() with base 10: 'is_completed'

During handling of the above exception, another exception occurred:

Traceback (most recent call last):
  File "C:\Python312\Lib\site-packages\django\template\base.py", line 906, in _resolve_lookup
    raise VariableDoesNotExist(
django.template.base.VariableDoesNotExist: Failed lookup for key [is_completed] in <Examination: Examination for psyc D. mann on 2024-12-23>
DEBUG 2024-12-23 19:59:21,320 base 15672 4972 Exception while resolving variable 'is_completed' in template 'secretary_dash/doctor/examination_list.html'.
Traceback (most recent call last):
  File "C:\Python312\Lib\site-packages\django\template\base.py", line 883, in _resolve_lookup
    current = current[bit]
              ~~~~~~~^^^^^
TypeError: 'Examination' object is not subscriptable

During handling of the above exception, another exception occurred:

Traceback (most recent call last):
  File "C:\Python312\Lib\site-packages\django\template\base.py", line 893, in _resolve_lookup
    current = getattr(current, bit)
              ^^^^^^^^^^^^^^^^^^^^^
AttributeError: 'Examination' object has no attribute 'is_completed'

During handling of the above exception, another exception occurred:

Traceback (most recent call last):
  File "C:\Python312\Lib\site-packages\django\template\base.py", line 899, in _resolve_lookup
    current = current[int(bit)]
                      ^^^^^^^^
ValueError: invalid literal for int() with base 10: 'is_completed'

During handling of the above exception, another exception occurred:

Traceback (most recent call last):
  File "C:\Python312\Lib\site-packages\django\template\base.py", line 906, in _resolve_lookup
    raise VariableDoesNotExist(
django.template.base.VariableDoesNotExist: Failed lookup for key [is_completed] in <Examination: Examination for psyc D. mann on 2024-12-23>
DEBUG 2024-12-23 19:59:21,325 base 15672 4972 Exception while resolving variable 'is_completed' in template 'secretary_dash/doctor/examination_list.html'.
Traceback (most recent call last):
  File "C:\Python312\Lib\site-packages\django\template\base.py", line 883, in _resolve_lookup
    current = current[bit]
              ~~~~~~~^^^^^
TypeError: 'Examination' object is not subscriptable

During handling of the above exception, another exception occurred:

Traceback (most recent call last):
  File "C:\Python312\Lib\site-packages\django\template\base.py", line 893, in _resolve_lookup
    current = getattr(current, bit)
              ^^^^^^^^^^^^^^^^^^^^^
AttributeError: 'Examination' object has no attribute 'is_completed'

During handling of the above exception, another exception occurred:

Traceback (most recent call last):
  File "C:\Python312\Lib\site-packages\django\template\base.py", line 899, in _resolve_lookup
    current = current[int(bit)]
                      ^^^^^^^^
ValueError: invalid literal for int() with base 10: 'is_completed'

During handling of the above exception, another exception occurred:

Traceback (most recent call last):
  File "C:\Python312\Lib\site-packages\django\template\base.py", line 906, in _resolve_lookup
    raise VariableDoesNotExist(
django.template.base.VariableDoesNotExist: Failed lookup for key [is_completed] in <Examination: Examination for Sickly De Santos on 2024-12-23>
DEBUG 2024-12-23 19:59:21,325 base 15672 4972 Exception while resolving variable 'is_completed' in template 'secretary_dash/doctor/examination_list.html'.
Traceback (most recent call last):
  File "C:\Python312\Lib\site-packages\django\template\base.py", line 883, in _resolve_lookup
    current = current[bit]
              ~~~~~~~^^^^^
TypeError: 'Examination' object is not subscriptable

During handling of the above exception, another exception occurred:

Traceback (most recent call last):
  File "C:\Python312\Lib\site-packages\django\template\base.py", line 893, in _resolve_lookup
    current = getattr(current, bit)
              ^^^^^^^^^^^^^^^^^^^^^
AttributeError: 'Examination' object has no attribute 'is_completed'

During handling of the above exception, another exception occurred:

Traceback (most recent call last):
  File "C:\Python312\Lib\site-packages\django\template\base.py", line 899, in _resolve_lookup
    current = current[int(bit)]
                      ^^^^^^^^
ValueError: invalid literal for int() with base 10: 'is_completed'

During handling of the above exception, another exception occurred:

Traceback (most recent call last):
  File "C:\Python312\Lib\site-packages\django\template\base.py", line 906, in _resolve_lookup
    raise VariableDoesNotExist(
django.template.base.VariableDoesNotExist: Failed lookup for key [is_completed] in <Examination: Examination for Sickly De Santos on 2024-12-23>
DEBUG 2024-12-23 19:59:21,329 base 15672 4972 Exception while resolving variable 'is_completed' in template 'secretary_dash/doctor/examination_list.html'.
Traceback (most recent call last):
  File "C:\Python312\Lib\site-packages\django\template\base.py", line 883, in _resolve_lookup
    current = current[bit]
              ~~~~~~~^^^^^
TypeError: 'Examination' object is not subscriptable

During handling of the above exception, another exception occurred:

Traceback (most recent call last):
  File "C:\Python312\Lib\site-packages\django\template\base.py", line 893, in _resolve_lookup
    current = getattr(current, bit)
              ^^^^^^^^^^^^^^^^^^^^^
AttributeError: 'Examination' object has no attribute 'is_completed'

During handling of the above exception, another exception occurred:

Traceback (most recent call last):
  File "C:\Python312\Lib\site-packages\django\template\base.py", line 899, in _resolve_lookup
    current = current[int(bit)]
                      ^^^^^^^^
ValueError: invalid literal for int() with base 10: 'is_completed'

During handling of the above exception, another exception occurred:

Traceback (most recent call last):
  File "C:\Python312\Lib\site-packages\django\template\base.py", line 906, in _resolve_lookup
    raise VariableDoesNotExist(
django.template.base.VariableDoesNotExist: Failed lookup for key [is_completed] in <Examination: Examination for John doe on 2024-12-23>
DEBUG 2024-12-23 19:59:21,329 base 15672 4972 Exception while resolving variable 'is_completed' in template 'secretary_dash/doctor/examination_list.html'.
Traceback (most recent call last):
  File "C:\Python312\Lib\site-packages\django\template\base.py", line 883, in _resolve_lookup
    current = current[bit]
              ~~~~~~~^^^^^
TypeError: 'Examination' object is not subscriptable

During handling of the above exception, another exception occurred:

Traceback (most recent call last):
  File "C:\Python312\Lib\site-packages\django\template\base.py", line 893, in _resolve_lookup
    current = getattr(current, bit)
              ^^^^^^^^^^^^^^^^^^^^^
AttributeError: 'Examination' object has no attribute 'is_completed'

During handling of the above exception, another exception occurred:

Traceback (most recent call last):
  File "C:\Python312\Lib\site-packages\django\template\base.py", line 899, in _resolve_lookup
    current = current[int(bit)]
                      ^^^^^^^^
ValueError: invalid literal for int() with base 10: 'is_completed'

During handling of the above exception, another exception occurred:

Traceback (most recent call last):
  File "C:\Python312\Lib\site-packages\django\template\base.py", line 906, in _resolve_lookup
    raise VariableDoesNotExist(
django.template.base.VariableDoesNotExist: Failed lookup for key [is_completed] in <Examination: Examination for John doe on 2024-12-23>
DEBUG 2024-12-23 19:59:21,334 base 15672 4972 Exception while resolving variable 'is_completed' in template 'secretary_dash/doctor/examination_list.html'.
Traceback (most recent call last):
  File "C:\Python312\Lib\site-packages\django\template\base.py", line 883, in _resolve_lookup
    current = current[bit]
              ~~~~~~~^^^^^
TypeError: 'Examination' object is not subscriptable

During handling of the above exception, another exception occurred:

Traceback (most recent call last):
  File "C:\Python312\Lib\site-packages\django\template\base.py", line 893, in _resolve_lookup
    current = getattr(current, bit)
              ^^^^^^^^^^^^^^^^^^^^^
AttributeError: 'Examination' object has no attribute 'is_completed'

During handling of the above exception, another exception occurred:

Traceback (most recent call last):
  File "C:\Python312\Lib\site-packages\django\template\base.py", line 899, in _resolve_lookup
    current = current[int(bit)]
                      ^^^^^^^^
ValueError: invalid literal for int() with base 10: 'is_completed'

During handling of the above exception, another exception occurred:

Traceback (most recent call last):
  File "C:\Python312\Lib\site-packages\django\template\base.py", line 906, in _resolve_lookup
    raise VariableDoesNotExist(
django.template.base.VariableDoesNotExist: Failed lookup for key [is_completed] in <Examination: Examination for psyc D. mann on 2024-12-22>
DEBUG 2024-12-23 19:59:21,334 base 15672 4972 Exception while resolving variable 'is_completed' in template 'secretary_dash/doctor/examination_list.html'.
Traceback (most recent call last):
  File "C:\Python312\Lib\site-packages\django\template\base.py", line 883, in _resolve_lookup
    current = current[bit]
              ~~~~~~~^^^^^
TypeError: 'Examination' object is not subscriptable

During handling of the above exception, another exception occurred:

Traceback (most recent call last):
  File "C:\Python312\Lib\site-packages\django\template\base.py", line 893, in _resolve_lookup
    current = getattr(current, bit)
              ^^^^^^^^^^^^^^^^^^^^^
AttributeError: 'Examination' object has no attribute 'is_completed'

During handling of the above exception, another exception occurred:

Traceback (most recent call last):
  File "C:\Python312\Lib\site-packages\django\template\base.py", line 899, in _resolve_lookup
    current = current[int(bit)]
                      ^^^^^^^^
ValueError: invalid literal for int() with base 10: 'is_completed'

During handling of the above exception, another exception occurred:

Traceback (most recent call last):
  File "C:\Python312\Lib\site-packages\django\template\base.py", line 906, in _resolve_lookup
    raise VariableDoesNotExist(
django.template.base.VariableDoesNotExist: Failed lookup for key [is_completed] in <Examination: Examination for psyc D. mann on 2024-12-22>
INFO 2024-12-23 19:59:21,337 basehttp 15672 4972 "GET /examinations/ HTTP/1.1" 200 11570
INFO 2024-12-23 19:59:50,087 basehttp 15672 4972 "GET /appointments/ HTTP/1.1" 200 12867
INFO 2024-12-23 19:59:50,715 basehttp 15672 4972 "GET /medicines/ HTTP/1.1" 200 8526
INFO 2024-12-23 19:59:51,131 basehttp 15672 4972 "GET /patients/ HTTP/1.1" 200 11564
INFO 2024-12-23 19:59:51,477 basehttp 15672 4972 "GET /doctor/secretaries/ HTTP/1.1" 200 7603
DEBUG 2024-12-23 19:59:52,001 base 15672 4972 Exception while resolving variable 'reason' in template 'secretary_dash/doctor/dashboard.html'.
Traceback (most recent call last):
  File "C:\Python312\Lib\site-packages\django\template\base.py", line 883, in _resolve_lookup
    current = current[bit]
              ~~~~~~~^^^^^
TypeError: 'Appointment' object is not subscriptable

During handling of the above exception, another exception occurred:

Traceback (most recent call last):
  File "C:\Python312\Lib\site-packages\django\template\base.py", line 893, in _resolve_lookup
    current = getattr(current, bit)
              ^^^^^^^^^^^^^^^^^^^^^
AttributeError: 'Appointment' object has no attribute 'reason'

During handling of the above exception, another exception occurred:

Traceback (most recent call last):
  File "C:\Python312\Lib\site-packages\django\template\base.py", line 899, in _resolve_lookup
    current = current[int(bit)]
                      ^^^^^^^^
ValueError: invalid literal for int() with base 10: 'reason'

During handling of the above exception, another exception occurred:

Traceback (most recent call last):
  File "C:\Python312\Lib\site-packages\django\template\base.py", line 906, in _resolve_lookup
    raise VariableDoesNotExist(
django.template.base.VariableDoesNotExist: Failed lookup for key [reason] in <Appointment: Sickly De Santos - 2024-12-23 09:00>
DEBUG 2024-12-23 19:59:52,001 base 15672 4972 Exception while resolving variable 'reason' in template 'secretary_dash/doctor/dashboard.html'.
Traceback (most recent call last):
  File "C:\Python312\Lib\site-packages\django\template\base.py", line 883, in _resolve_lookup
    current = current[bit]
              ~~~~~~~^^^^^
TypeError: 'Appointment' object is not subscriptable

During handling of the above exception, another exception occurred:

Traceback (most recent call last):
  File "C:\Python312\Lib\site-packages\django\template\base.py", line 893, in _resolve_lookup
    current = getattr(current, bit)
              ^^^^^^^^^^^^^^^^^^^^^
AttributeError: 'Appointment' object has no attribute 'reason'

During handling of the above exception, another exception occurred:

Traceback (most recent call last):
  File "C:\Python312\Lib\site-packages\django\template\base.py", line 899, in _resolve_lookup
    current = current[int(bit)]
                      ^^^^^^^^
ValueError: invalid literal for int() with base 10: 'reason'

During handling of the above exception, another exception occurred:

Traceback (most recent call last):
  File "C:\Python312\Lib\site-packages\django\template\base.py", line 906, in _resolve_lookup
    raise VariableDoesNotExist(
django.template.base.VariableDoesNotExist: Failed lookup for key [reason] in <Appointment: Sickly De Santos - 2024-12-23 09:00>
DEBUG 2024-12-23 19:59:52,003 base 15672 4972 Exception while resolving variable 'reason' in template 'secretary_dash/doctor/dashboard.html'.
Traceback (most recent call last):
  File "C:\Python312\Lib\site-packages\django\template\base.py", line 883, in _resolve_lookup
    current = current[bit]
              ~~~~~~~^^^^^
TypeError: 'Appointment' object is not subscriptable

During handling of the above exception, another exception occurred:

Traceback (most recent call last):
  File "C:\Python312\Lib\site-packages\django\template\base.py", line 893, in _resolve_lookup
    current = getattr(current, bit)
              ^^^^^^^^^^^^^^^^^^^^^
AttributeError: 'Appointment' object has no attribute 'reason'

During handling of the above exception, another exception occurred:

Traceback (most recent call last):
  File "C:\Python312\Lib\site-packages\django\template\base.py", line 899, in _resolve_lookup
    current = current[int(bit)]
                      ^^^^^^^^
ValueError: invalid literal for int() with base 10: 'reason'

During handling of the above exception, another exception occurred:

Traceback (most recent call last):
  File "C:\Python312\Lib\site-packages\django\template\base.py", line 906, in _resolve_lookup
    raise VariableDoesNotExist(
django.template.base.VariableDoesNotExist: Failed lookup for key [reason] in <Appointment: John doe - 2024-12-23 10:30>
DEBUG 2024-12-23 19:59:52,003 base 15672 4972 Exception while resolving variable 'reason' in template 'secretary_dash/doctor/dashboard.html'.
Traceback (most recent call last):
  File "C:\Python312\Lib\site-packages\django\template\base.py", line 883, in _resolve_lookup
    current = current[bit]
              ~~~~~~~^^^^^
TypeError: 'Appointment' object is not subscriptable

During handling of the above exception, another exception occurred:

Traceback (most recent call last):
  File "C:\Python312\Lib\site-packages\django\template\base.py", line 893, in _resolve_lookup
    current = getattr(current, bit)
              ^^^^^^^^^^^^^^^^^^^^^
AttributeError: 'Appointment' object has no attribute 'reason'

During handling of the above exception, another exception occurred:

Traceback (most recent call last):
  File "C:\Python312\Lib\site-packages\django\template\base.py", line 899, in _resolve_lookup
    current = current[int(bit)]
                      ^^^^^^^^
ValueError: invalid literal for int() with base 10: 'reason'

During handling of the above exception, another exception occurred:

Traceback (most recent call last):
  File "C:\Python312\Lib\site-packages\django\template\base.py", line 906, in _resolve_lookup
    raise VariableDoesNotExist(
django.template.base.VariableDoesNotExist: Failed lookup for key [reason] in <Appointment: John doe - 2024-12-23 10:30>
DEBUG 2024-12-23 19:59:52,004 base 15672 4972 Exception while resolving variable 'reason' in template 'secretary_dash/doctor/dashboard.html'.
Traceback (most recent call last):
  File "C:\Python312\Lib\site-packages\django\template\base.py", line 883, in _resolve_lookup
    current = current[bit]
              ~~~~~~~^^^^^
TypeError: 'Appointment' object is not subscriptable

During handling of the above exception, another exception occurred:

Traceback (most recent call last):
  File "C:\Python312\Lib\site-packages\django\template\base.py", line 893, in _resolve_lookup
    current = getattr(current, bit)
              ^^^^^^^^^^^^^^^^^^^^^
AttributeError: 'Appointment' object has no attribute 'reason'

During handling of the above exception, another exception occurred:

Traceback (most recent call last):
  File "C:\Python312\Lib\site-packages\django\template\base.py", line 899, in _resolve_lookup
    current = current[int(bit)]
                      ^^^^^^^^
ValueError: invalid literal for int() with base 10: 'reason'

During handling of the above exception, another exception occurred:

Traceback (most recent call last):
  File "C:\Python312\Lib\site-packages\django\template\base.py", line 906, in _resolve_lookup
    raise VariableDoesNotExist(
django.template.base.VariableDoesNotExist: Failed lookup for key [reason] in <Appointment: psyc D. mann - 2024-12-23 12:00>
DEBUG 2024-12-23 19:59:52,004 base 15672 4972 Exception while resolving variable 'reason' in template 'secretary_dash/doctor/dashboard.html'.
Traceback (most recent call last):
  File "C:\Python312\Lib\site-packages\django\template\base.py", line 883, in _resolve_lookup
    current = current[bit]
              ~~~~~~~^^^^^
TypeError: 'Appointment' object is not subscriptable

During handling of the above exception, another exception occurred:

Traceback (most recent call last):
  File "C:\Python312\Lib\site-packages\django\template\base.py", line 893, in _resolve_lookup
    current = getattr(current, bit)
              ^^^^^^^^^^^^^^^^^^^^^
AttributeError: 'Appointment' object has no attribute 'reason'

During handling of the above exception, another exception occurred:

Traceback (most recent call last):
  File "C:\Python312\Lib\site-packages\django\template\base.py", line 899, in _resolve_lookup
    current = current[int(bit)]
                      ^^^^^^^^
ValueError: invalid literal for int() with base 10: 'reason'

During handling of the above exception, another exception occurred:

Traceback (most recent call last):
  File "C:\Python312\Lib\site-packages\django\template\base.py", line 906, in _resolve_lookup
    raise VariableDoesNotExist(
django.template.base.VariableDoesNotExist: Failed lookup for key [reason] in <Appointment: psyc D. mann - 2024-12-23 12:00>
DEBUG 2024-12-23 19:59:52,005 base 15672 4972 Exception while resolving variable 'reason' in template 'secretary_dash/doctor/dashboard.html'.
Traceback (most recent call last):
  File "C:\Python312\Lib\site-packages\django\template\base.py", line 883, in _resolve_lookup
    current = current[bit]
              ~~~~~~~^^^^^
TypeError: 'Appointment' object is not subscriptable

During handling of the above exception, another exception occurred:

Traceback (most recent call last):
  File "C:\Python312\Lib\site-packages\django\template\base.py", line 893, in _resolve_lookup
    current = getattr(current, bit)
              ^^^^^^^^^^^^^^^^^^^^^
AttributeError: 'Appointment' object has no attribute 'reason'

During handling of the above exception, another exception occurred:

Traceback (most recent call last):
  File "C:\Python312\Lib\site-packages\django\template\base.py", line 899, in _resolve_lookup
    current = current[int(bit)]
                      ^^^^^^^^
ValueError: invalid literal for int() with base 10: 'reason'

During handling of the above exception, another exception occurred:

Traceback (most recent call last):
  File "C:\Python312\Lib\site-packages\django\template\base.py", line 906, in _resolve_lookup
    raise VariableDoesNotExist(
django.template.base.VariableDoesNotExist: Failed lookup for key [reason] in <Appointment: psyc D. mann - 2024-12-23 14:00>
DEBUG 2024-12-23 19:59:52,005 base 15672 4972 Exception while resolving variable 'reason' in template 'secretary_dash/doctor/dashboard.html'.
Traceback (most recent call last):
  File "C:\Python312\Lib\site-packages\django\template\base.py", line 883, in _resolve_lookup
    current = current[bit]
              ~~~~~~~^^^^^
TypeError: 'Appointment' object is not subscriptable

During handling of the above exception, another exception occurred:

Traceback (most recent call last):
  File "C:\Python312\Lib\site-packages\django\template\base.py", line 893, in _resolve_lookup
    current = getattr(current, bit)
              ^^^^^^^^^^^^^^^^^^^^^
AttributeError: 'Appointment' object has no attribute 'reason'

During handling of the above exception, another exception occurred:

Traceback (most recent call last):
  File "C:\Python312\Lib\site-packages\django\template\base.py", line 899, in _resolve_lookup
    current = current[int(bit)]
                      ^^^^^^^^
ValueError: invalid literal for int() with base 10: 'reason'

During handling of the above exception, another exception occurred:

Traceback (most recent call last):
  File "C:\Python312\Lib\site-packages\django\template\base.py", line 906, in _resolve_lookup
    raise VariableDoesNotExist(
django.template.base.VariableDoesNotExist: Failed lookup for key [reason] in <Appointment: psyc D. mann - 2024-12-23 14:00>
DEBUG 2024-12-23 19:59:52,007 base 15672 4972 Exception while resolving variable 'reason' in template 'secretary_dash/doctor/dashboard.html'.
Traceback (most recent call last):
  File "C:\Python312\Lib\site-packages\django\template\base.py", line 883, in _resolve_lookup
    current = current[bit]
              ~~~~~~~^^^^^
TypeError: 'Appointment' object is not subscriptable

During handling of the above exception, another exception occurred:

Traceback (most recent call last):
  File "C:\Python312\Lib\site-packages\django\template\base.py", line 893, in _resolve_lookup
    current = getattr(current, bit)
              ^^^^^^^^^^^^^^^^^^^^^
AttributeError: 'Appointment' object has no attribute 'reason'

During handling of the above exception, another exception occurred:

Traceback (most recent call last):
  File "C:\Python312\Lib\site-packages\django\template\base.py", line 899, in _resolve_lookup
    current = current[int(bit)]
                      ^^^^^^^^
ValueError: invalid literal for int() with base 10: 'reason'

During handling of the above exception, another exception occurred:

Traceback (most recent call last):
  File "C:\Python312\Lib\site-packages\django\template\base.py", line 906, in _resolve_lookup
    raise VariableDoesNotExist(
django.template.base.VariableDoesNotExist: Failed lookup for key [reason] in <Appointment: Corey V. Depen - 2024-12-23 16:00>
DEBUG 2024-12-23 19:59:52,007 base 15672 4972 Exception while resolving variable 'reason' in template 'secretary_dash/doctor/dashboard.html'.
Traceback (most recent call last):
  File "C:\Python312\Lib\site-packages\django\template\base.py", line 883, in _resolve_lookup
    current = current[bit]
              ~~~~~~~^^^^^
TypeError: 'Appointment' object is not subscriptable

During handling of the above exception, another exception occurred:

Traceback (most recent call last):
  File "C:\Python312\Lib\site-packages\django\template\base.py", line 893, in _resolve_lookup
    current = getattr(current, bit)
              ^^^^^^^^^^^^^^^^^^^^^
AttributeError: 'Appointment' object has no attribute 'reason'

During handling of the above exception, another exception occurred:

Traceback (most recent call last):
  File "C:\Python312\Lib\site-packages\django\template\base.py", line 899, in _resolve_lookup
    current = current[int(bit)]
                      ^^^^^^^^
ValueError: invalid literal for int() with base 10: 'reason'

During handling of the above exception, another exception occurred:

Traceback (most recent call last):
  File "C:\Python312\Lib\site-packages\django\template\base.py", line 906, in _resolve_lookup
    raise VariableDoesNotExist(
django.template.base.VariableDoesNotExist: Failed lookup for key [reason] in <Appointment: Corey V. Depen - 2024-12-23 16:00>
INFO 2024-12-23 19:59:52,008 basehttp 15672 4972 "GET /doctor/ HTTP/1.1" 200 33508
INFO 2024-12-23 19:59:52,573 basehttp 15672 4972 "GET /doctor/secretaries/ HTTP/1.1" 200 7603
INFO 2024-12-23 19:59:53,353 basehttp 15672 4972 "GET /patients/ HTTP/1.1" 200 11564
INFO 2024-12-23 19:59:54,490 basehttp 15672 4972 "GET /medicines/ HTTP/1.1" 200 8526
INFO 2024-12-23 19:59:55,174 basehttp 15672 4972 "GET /appointments/ HTTP/1.1" 200 12867
DEBUG 2024-12-23 19:59:55,610 base 15672 4972 Exception while resolving variable 'is_completed' in template 'secretary_dash/doctor/examination_list.html'.
Traceback (most recent call last):
  File "C:\Python312\Lib\site-packages\django\template\base.py", line 883, in _resolve_lookup
    current = current[bit]
              ~~~~~~~^^^^^
TypeError: 'Examination' object is not subscriptable

During handling of the above exception, another exception occurred:

Traceback (most recent call last):
  File "C:\Python312\Lib\site-packages\django\template\base.py", line 893, in _resolve_lookup
    current = getattr(current, bit)
              ^^^^^^^^^^^^^^^^^^^^^
AttributeError: 'Examination' object has no attribute 'is_completed'

During handling of the above exception, another exception occurred:

Traceback (most recent call last):
  File "C:\Python312\Lib\site-packages\django\template\base.py", line 899, in _resolve_lookup
    current = current[int(bit)]
                      ^^^^^^^^
ValueError: invalid literal for int() with base 10: 'is_completed'

During handling of the above exception, another exception occurred:

Traceback (most recent call last):
  File "C:\Python312\Lib\site-packages\django\template\base.py", line 906, in _resolve_lookup
    raise VariableDoesNotExist(
django.template.base.VariableDoesNotExist: Failed lookup for key [is_completed] in <Examination: Examination for psyc D. mann on 2024-12-23>
DEBUG 2024-12-23 19:59:55,610 base 15672 4972 Exception while resolving variable 'is_completed' in template 'secretary_dash/doctor/examination_list.html'.
Traceback (most recent call last):
  File "C:\Python312\Lib\site-packages\django\template\base.py", line 883, in _resolve_lookup
    current = current[bit]
              ~~~~~~~^^^^^
TypeError: 'Examination' object is not subscriptable

During handling of the above exception, another exception occurred:

Traceback (most recent call last):
  File "C:\Python312\Lib\site-packages\django\template\base.py", line 893, in _resolve_lookup
    current = getattr(current, bit)
              ^^^^^^^^^^^^^^^^^^^^^
AttributeError: 'Examination' object has no attribute 'is_completed'

During handling of the above exception, another exception occurred:

Traceback (most recent call last):
  File "C:\Python312\Lib\site-packages\django\template\base.py", line 899, in _resolve_lookup
    current = current[int(bit)]
                      ^^^^^^^^
ValueError: invalid literal for int() with base 10: 'is_completed'

During handling of the above exception, another exception occurred:

Traceback (most recent call last):
  File "C:\Python312\Lib\site-packages\django\template\base.py", line 906, in _resolve_lookup
    raise VariableDoesNotExist(
django.template.base.VariableDoesNotExist: Failed lookup for key [is_completed] in <Examination: Examination for psyc D. mann on 2024-12-23>
DEBUG 2024-12-23 19:59:55,613 base 15672 4972 Exception while resolving variable 'is_completed' in template 'secretary_dash/doctor/examination_list.html'.
Traceback (most recent call last):
  File "C:\Python312\Lib\site-packages\django\template\base.py", line 883, in _resolve_lookup
    current = current[bit]
              ~~~~~~~^^^^^
TypeError: 'Examination' object is not subscriptable

During handling of the above exception, another exception occurred:

Traceback (most recent call last):
  File "C:\Python312\Lib\site-packages\django\template\base.py", line 893, in _resolve_lookup
    current = getattr(current, bit)
              ^^^^^^^^^^^^^^^^^^^^^
AttributeError: 'Examination' object has no attribute 'is_completed'

During handling of the above exception, another exception occurred:

Traceback (most recent call last):
  File "C:\Python312\Lib\site-packages\django\template\base.py", line 899, in _resolve_lookup
    current = current[int(bit)]
                      ^^^^^^^^
ValueError: invalid literal for int() with base 10: 'is_completed'

During handling of the above exception, another exception occurred:

Traceback (most recent call last):
  File "C:\Python312\Lib\site-packages\django\template\base.py", line 906, in _resolve_lookup
    raise VariableDoesNotExist(
django.template.base.VariableDoesNotExist: Failed lookup for key [is_completed] in <Examination: Examination for Sickly De Santos on 2024-12-23>
DEBUG 2024-12-23 19:59:55,613 base 15672 4972 Exception while resolving variable 'is_completed' in template 'secretary_dash/doctor/examination_list.html'.
Traceback (most recent call last):
  File "C:\Python312\Lib\site-packages\django\template\base.py", line 883, in _resolve_lookup
    current = current[bit]
              ~~~~~~~^^^^^
TypeError: 'Examination' object is not subscriptable

During handling of the above exception, another exception occurred:

Traceback (most recent call last):
  File "C:\Python312\Lib\site-packages\django\template\base.py", line 893, in _resolve_lookup
    current = getattr(current, bit)
              ^^^^^^^^^^^^^^^^^^^^^
AttributeError: 'Examination' object has no attribute 'is_completed'

During handling of the above exception, another exception occurred:

Traceback (most recent call last):
  File "C:\Python312\Lib\site-packages\django\template\base.py", line 899, in _resolve_lookup
    current = current[int(bit)]
                      ^^^^^^^^
ValueError: invalid literal for int() with base 10: 'is_completed'

During handling of the above exception, another exception occurred:

Traceback (most recent call last):
  File "C:\Python312\Lib\site-packages\django\template\base.py", line 906, in _resolve_lookup
    raise VariableDoesNotExist(
django.template.base.VariableDoesNotExist: Failed lookup for key [is_completed] in <Examination: Examination for Sickly De Santos on 2024-12-23>
DEBUG 2024-12-23 19:59:55,615 base 15672 4972 Exception while resolving variable 'is_completed' in template 'secretary_dash/doctor/examination_list.html'.
Traceback (most recent call last):
  File "C:\Python312\Lib\site-packages\django\template\base.py", line 883, in _resolve_lookup
    current = current[bit]
              ~~~~~~~^^^^^
TypeError: 'Examination' object is not subscriptable

During handling of the above exception, another exception occurred:

Traceback (most recent call last):
  File "C:\Python312\Lib\site-packages\django\template\base.py", line 893, in _resolve_lookup
    current = getattr(current, bit)
              ^^^^^^^^^^^^^^^^^^^^^
AttributeError: 'Examination' object has no attribute 'is_completed'

During handling of the above exception, another exception occurred:

Traceback (most recent call last):
  File "C:\Python312\Lib\site-packages\django\template\base.py", line 899, in _resolve_lookup
    current = current[int(bit)]
                      ^^^^^^^^
ValueError: invalid literal for int() with base 10: 'is_completed'

During handling of the above exception, another exception occurred:

Traceback (most recent call last):
  File "C:\Python312\Lib\site-packages\django\template\base.py", line 906, in _resolve_lookup
    raise VariableDoesNotExist(
django.template.base.VariableDoesNotExist: Failed lookup for key [is_completed] in <Examination: Examination for John doe on 2024-12-23>
DEBUG 2024-12-23 19:59:55,615 base 15672 4972 Exception while resolving variable 'is_completed' in template 'secretary_dash/doctor/examination_list.html'.
Traceback (most recent call last):
  File "C:\Python312\Lib\site-packages\django\template\base.py", line 883, in _resolve_lookup
    current = current[bit]
              ~~~~~~~^^^^^
TypeError: 'Examination' object is not subscriptable

During handling of the above exception, another exception occurred:

Traceback (most recent call last):
  File "C:\Python312\Lib\site-packages\django\template\base.py", line 893, in _resolve_lookup
    current = getattr(current, bit)
              ^^^^^^^^^^^^^^^^^^^^^
AttributeError: 'Examination' object has no attribute 'is_completed'

During handling of the above exception, another exception occurred:

Traceback (most recent call last):
  File "C:\Python312\Lib\site-packages\django\template\base.py", line 899, in _resolve_lookup
    current = current[int(bit)]
                      ^^^^^^^^
ValueError: invalid literal for int() with base 10: 'is_completed'

During handling of the above exception, another exception occurred:

Traceback (most recent call last):
  File "C:\Python312\Lib\site-packages\django\template\base.py", line 906, in _resolve_lookup
    raise VariableDoesNotExist(
django.template.base.VariableDoesNotExist: Failed lookup for key [is_completed] in <Examination: Examination for John doe on 2024-12-23>
DEBUG 2024-12-23 19:59:55,618 base 15672 4972 Exception while resolving variable 'is_completed' in template 'secretary_dash/doctor/examination_list.html'.
Traceback (most recent call last):
  File "C:\Python312\Lib\site-packages\django\template\base.py", line 883, in _resolve_lookup
    current = current[bit]
              ~~~~~~~^^^^^
TypeError: 'Examination' object is not subscriptable

During handling of the above exception, another exception occurred:

Traceback (most recent call last):
  File "C:\Python312\Lib\site-packages\django\template\base.py", line 893, in _resolve_lookup
    current = getattr(current, bit)
              ^^^^^^^^^^^^^^^^^^^^^
AttributeError: 'Examination' object has no attribute 'is_completed'

During handling of the above exception, another exception occurred:

Traceback (most recent call last):
  File "C:\Python312\Lib\site-packages\django\template\base.py", line 899, in _resolve_lookup
    current = current[int(bit)]
                      ^^^^^^^^
ValueError: invalid literal for int() with base 10: 'is_completed'

During handling of the above exception, another exception occurred:

Traceback (most recent call last):
  File "C:\Python312\Lib\site-packages\django\template\base.py", line 906, in _resolve_lookup
    raise VariableDoesNotExist(
django.template.base.VariableDoesNotExist: Failed lookup for key [is_completed] in <Examination: Examination for psyc D. mann on 2024-12-22>
DEBUG 2024-12-23 19:59:55,618 base 15672 4972 Exception while resolving variable 'is_completed' in template 'secretary_dash/doctor/examination_list.html'.
Traceback (most recent call last):
  File "C:\Python312\Lib\site-packages\django\template\base.py", line 883, in _resolve_lookup
    current = current[bit]
              ~~~~~~~^^^^^
TypeError: 'Examination' object is not subscriptable

During handling of the above exception, another exception occurred:

Traceback (most recent call last):
  File "C:\Python312\Lib\site-packages\django\template\base.py", line 893, in _resolve_lookup
    current = getattr(current, bit)
              ^^^^^^^^^^^^^^^^^^^^^
AttributeError: 'Examination' object has no attribute 'is_completed'

During handling of the above exception, another exception occurred:

Traceback (most recent call last):
  File "C:\Python312\Lib\site-packages\django\template\base.py", line 899, in _resolve_lookup
    current = current[int(bit)]
                      ^^^^^^^^
ValueError: invalid literal for int() with base 10: 'is_completed'

During handling of the above exception, another exception occurred:

Traceback (most recent call last):
  File "C:\Python312\Lib\site-packages\django\template\base.py", line 906, in _resolve_lookup
    raise VariableDoesNotExist(
django.template.base.VariableDoesNotExist: Failed lookup for key [is_completed] in <Examination: Examination for psyc D. mann on 2024-12-22>
INFO 2024-12-23 19:59:55,618 basehttp 15672 4972 "GET /examinations/ HTTP/1.1" 200 11570
INFO 2024-12-23 19:59:56,019 basehttp 15672 4972 "GET /doctor/busy-hours/ HTTP/1.1" 200 8765
DEBUG 2024-12-23 20:01:28,525 base 15672 4972 Exception while resolving variable 'is_completed' in template 'secretary_dash/doctor/examination_list.html'.
Traceback (most recent call last):
  File "C:\Python312\Lib\site-packages\django\template\base.py", line 883, in _resolve_lookup
    current = current[bit]
              ~~~~~~~^^^^^
TypeError: 'Examination' object is not subscriptable

During handling of the above exception, another exception occurred:

Traceback (most recent call last):
  File "C:\Python312\Lib\site-packages\django\template\base.py", line 893, in _resolve_lookup
    current = getattr(current, bit)
              ^^^^^^^^^^^^^^^^^^^^^
AttributeError: 'Examination' object has no attribute 'is_completed'

During handling of the above exception, another exception occurred:

Traceback (most recent call last):
  File "C:\Python312\Lib\site-packages\django\template\base.py", line 899, in _resolve_lookup
    current = current[int(bit)]
                      ^^^^^^^^
ValueError: invalid literal for int() with base 10: 'is_completed'

During handling of the above exception, another exception occurred:

Traceback (most recent call last):
  File "C:\Python312\Lib\site-packages\django\template\base.py", line 906, in _resolve_lookup
    raise VariableDoesNotExist(
django.template.base.VariableDoesNotExist: Failed lookup for key [is_completed] in <Examination: Examination for psyc D. mann on 2024-12-23>
DEBUG 2024-12-23 20:01:28,525 base 15672 4972 Exception while resolving variable 'is_completed' in template 'secretary_dash/doctor/examination_list.html'.
Traceback (most recent call last):
  File "C:\Python312\Lib\site-packages\django\template\base.py", line 883, in _resolve_lookup
    current = current[bit]
              ~~~~~~~^^^^^
TypeError: 'Examination' object is not subscriptable

During handling of the above exception, another exception occurred:

Traceback (most recent call last):
  File "C:\Python312\Lib\site-packages\django\template\base.py", line 893, in _resolve_lookup
    current = getattr(current, bit)
              ^^^^^^^^^^^^^^^^^^^^^
AttributeError: 'Examination' object has no attribute 'is_completed'

During handling of the above exception, another exception occurred:

Traceback (most recent call last):
  File "C:\Python312\Lib\site-packages\django\template\base.py", line 899, in _resolve_lookup
    current = current[int(bit)]
                      ^^^^^^^^
ValueError: invalid literal for int() with base 10: 'is_completed'

During handling of the above exception, another exception occurred:

Traceback (most recent call last):
  File "C:\Python312\Lib\site-packages\django\template\base.py", line 906, in _resolve_lookup
    raise VariableDoesNotExist(
django.template.base.VariableDoesNotExist: Failed lookup for key [is_completed] in <Examination: Examination for psyc D. mann on 2024-12-23>
DEBUG 2024-12-23 20:01:28,528 base 15672 4972 Exception while resolving variable 'is_completed' in template 'secretary_dash/doctor/examination_list.html'.
Traceback (most recent call last):
  File "C:\Python312\Lib\site-packages\django\template\base.py", line 883, in _resolve_lookup
    current = current[bit]
              ~~~~~~~^^^^^
TypeError: 'Examination' object is not subscriptable

During handling of the above exception, another exception occurred:

Traceback (most recent call last):
  File "C:\Python312\Lib\site-packages\django\template\base.py", line 893, in _resolve_lookup
    current = getattr(current, bit)
              ^^^^^^^^^^^^^^^^^^^^^
AttributeError: 'Examination' object has no attribute 'is_completed'

During handling of the above exception, another exception occurred:

Traceback (most recent call last):
  File "C:\Python312\Lib\site-packages\django\template\base.py", line 899, in _resolve_lookup
    current = current[int(bit)]
                      ^^^^^^^^
ValueError: invalid literal for int() with base 10: 'is_completed'

During handling of the above exception, another exception occurred:

Traceback (most recent call last):
  File "C:\Python312\Lib\site-packages\django\template\base.py", line 906, in _resolve_lookup
    raise VariableDoesNotExist(
django.template.base.VariableDoesNotExist: Failed lookup for key [is_completed] in <Examination: Examination for Sickly De Santos on 2024-12-23>
DEBUG 2024-12-23 20:01:28,528 base 15672 4972 Exception while resolving variable 'is_completed' in template 'secretary_dash/doctor/examination_list.html'.
Traceback (most recent call last):
  File "C:\Python312\Lib\site-packages\django\template\base.py", line 883, in _resolve_lookup
    current = current[bit]
              ~~~~~~~^^^^^
TypeError: 'Examination' object is not subscriptable

During handling of the above exception, another exception occurred:

Traceback (most recent call last):
  File "C:\Python312\Lib\site-packages\django\template\base.py", line 893, in _resolve_lookup
    current = getattr(current, bit)
              ^^^^^^^^^^^^^^^^^^^^^
AttributeError: 'Examination' object has no attribute 'is_completed'

During handling of the above exception, another exception occurred:

Traceback (most recent call last):
  File "C:\Python312\Lib\site-packages\django\template\base.py", line 899, in _resolve_lookup
    current = current[int(bit)]
                      ^^^^^^^^
ValueError: invalid literal for int() with base 10: 'is_completed'

During handling of the above exception, another exception occurred:

Traceback (most recent call last):
  File "C:\Python312\Lib\site-packages\django\template\base.py", line 906, in _resolve_lookup
    raise VariableDoesNotExist(
django.template.base.VariableDoesNotExist: Failed lookup for key [is_completed] in <Examination: Examination for Sickly De Santos on 2024-12-23>
DEBUG 2024-12-23 20:01:28,529 base 15672 4972 Exception while resolving variable 'is_completed' in template 'secretary_dash/doctor/examination_list.html'.
Traceback (most recent call last):
  File "C:\Python312\Lib\site-packages\django\template\base.py", line 883, in _resolve_lookup
    current = current[bit]
              ~~~~~~~^^^^^
TypeError: 'Examination' object is not subscriptable

During handling of the above exception, another exception occurred:

Traceback (most recent call last):
  File "C:\Python312\Lib\site-packages\django\template\base.py", line 893, in _resolve_lookup
    current = getattr(current, bit)
              ^^^^^^^^^^^^^^^^^^^^^
AttributeError: 'Examination' object has no attribute 'is_completed'

During handling of the above exception, another exception occurred:

Traceback (most recent call last):
  File "C:\Python312\Lib\site-packages\django\template\base.py", line 899, in _resolve_lookup
    current = current[int(bit)]
                      ^^^^^^^^
ValueError: invalid literal for int() with base 10: 'is_completed'

During handling of the above exception, another exception occurred:

Traceback (most recent call last):
  File "C:\Python312\Lib\site-packages\django\template\base.py", line 906, in _resolve_lookup
    raise VariableDoesNotExist(
django.template.base.VariableDoesNotExist: Failed lookup for key [is_completed] in <Examination: Examination for John doe on 2024-12-23>
DEBUG 2024-12-23 20:01:28,529 base 15672 4972 Exception while resolving variable 'is_completed' in template 'secretary_dash/doctor/examination_list.html'.
Traceback (most recent call last):
  File "C:\Python312\Lib\site-packages\django\template\base.py", line 883, in _resolve_lookup
    current = current[bit]
              ~~~~~~~^^^^^
TypeError: 'Examination' object is not subscriptable

During handling of the above exception, another exception occurred:

Traceback (most recent call last):
  File "C:\Python312\Lib\site-packages\django\template\base.py", line 893, in _resolve_lookup
    current = getattr(current, bit)
              ^^^^^^^^^^^^^^^^^^^^^
AttributeError: 'Examination' object has no attribute 'is_completed'

During handling of the above exception, another exception occurred:

Traceback (most recent call last):
  File "C:\Python312\Lib\site-packages\django\template\base.py", line 899, in _resolve_lookup
    current = current[int(bit)]
                      ^^^^^^^^
ValueError: invalid literal for int() with base 10: 'is_completed'

During handling of the above exception, another exception occurred:

Traceback (most recent call last):
  File "C:\Python312\Lib\site-packages\django\template\base.py", line 906, in _resolve_lookup
    raise VariableDoesNotExist(
django.template.base.VariableDoesNotExist: Failed lookup for key [is_completed] in <Examination: Examination for John doe on 2024-12-23>
DEBUG 2024-12-23 20:01:28,532 base 15672 4972 Exception while resolving variable 'is_completed' in template 'secretary_dash/doctor/examination_list.html'.
Traceback (most recent call last):
  File "C:\Python312\Lib\site-packages\django\template\base.py", line 883, in _resolve_lookup
    current = current[bit]
              ~~~~~~~^^^^^
TypeError: 'Examination' object is not subscriptable

During handling of the above exception, another exception occurred:

Traceback (most recent call last):
  File "C:\Python312\Lib\site-packages\django\template\base.py", line 893, in _resolve_lookup
    current = getattr(current, bit)
              ^^^^^^^^^^^^^^^^^^^^^
AttributeError: 'Examination' object has no attribute 'is_completed'

During handling of the above exception, another exception occurred:

Traceback (most recent call last):
  File "C:\Python312\Lib\site-packages\django\template\base.py", line 899, in _resolve_lookup
    current = current[int(bit)]
                      ^^^^^^^^
ValueError: invalid literal for int() with base 10: 'is_completed'

During handling of the above exception, another exception occurred:

Traceback (most recent call last):
  File "C:\Python312\Lib\site-packages\django\template\base.py", line 906, in _resolve_lookup
    raise VariableDoesNotExist(
django.template.base.VariableDoesNotExist: Failed lookup for key [is_completed] in <Examination: Examination for psyc D. mann on 2024-12-22>
DEBUG 2024-12-23 20:01:28,532 base 15672 4972 Exception while resolving variable 'is_completed' in template 'secretary_dash/doctor/examination_list.html'.
Traceback (most recent call last):
  File "C:\Python312\Lib\site-packages\django\template\base.py", line 883, in _resolve_lookup
    current = current[bit]
              ~~~~~~~^^^^^
TypeError: 'Examination' object is not subscriptable

During handling of the above exception, another exception occurred:

Traceback (most recent call last):
  File "C:\Python312\Lib\site-packages\django\template\base.py", line 893, in _resolve_lookup
    current = getattr(current, bit)
              ^^^^^^^^^^^^^^^^^^^^^
AttributeError: 'Examination' object has no attribute 'is_completed'

During handling of the above exception, another exception occurred:

Traceback (most recent call last):
  File "C:\Python312\Lib\site-packages\django\template\base.py", line 899, in _resolve_lookup
    current = current[int(bit)]
                      ^^^^^^^^
ValueError: invalid literal for int() with base 10: 'is_completed'

During handling of the above exception, another exception occurred:

Traceback (most recent call last):
  File "C:\Python312\Lib\site-packages\django\template\base.py", line 906, in _resolve_lookup
    raise VariableDoesNotExist(
django.template.base.VariableDoesNotExist: Failed lookup for key [is_completed] in <Examination: Examination for psyc D. mann on 2024-12-22>
INFO 2024-12-23 20:01:28,534 basehttp 15672 4972 "GET /examinations/ HTTP/1.1" 200 11698
INFO 2024-12-23 20:01:30,301 basehttp 15672 4972 "GET /appointments/ HTTP/1.1" 200 12867
INFO 2024-12-23 20:01:30,618 basehttp 15672 4972 "GET /medicines/ HTTP/1.1" 200 8526
INFO 2024-12-23 20:01:30,958 basehttp 15672 4972 "GET /medicines/ HTTP/1.1" 200 8526
INFO 2024-12-23 20:01:31,338 basehttp 15672 4972 "GET /patients/ HTTP/1.1" 200 11564
INFO 2024-12-23 20:01:31,659 basehttp 15672 4972 "GET /doctor/secretaries/ HTTP/1.1" 200 7603
DEBUG 2024-12-23 20:01:31,958 base 15672 4972 Exception while resolving variable 'reason' in template 'secretary_dash/doctor/dashboard.html'.
Traceback (most recent call last):
  File "C:\Python312\Lib\site-packages\django\template\base.py", line 883, in _resolve_lookup
    current = current[bit]
              ~~~~~~~^^^^^
TypeError: 'Appointment' object is not subscriptable

During handling of the above exception, another exception occurred:

Traceback (most recent call last):
  File "C:\Python312\Lib\site-packages\django\template\base.py", line 893, in _resolve_lookup
    current = getattr(current, bit)
              ^^^^^^^^^^^^^^^^^^^^^
AttributeError: 'Appointment' object has no attribute 'reason'

During handling of the above exception, another exception occurred:

Traceback (most recent call last):
  File "C:\Python312\Lib\site-packages\django\template\base.py", line 899, in _resolve_lookup
    current = current[int(bit)]
                      ^^^^^^^^
ValueError: invalid literal for int() with base 10: 'reason'

During handling of the above exception, another exception occurred:

Traceback (most recent call last):
  File "C:\Python312\Lib\site-packages\django\template\base.py", line 906, in _resolve_lookup
    raise VariableDoesNotExist(
django.template.base.VariableDoesNotExist: Failed lookup for key [reason] in <Appointment: Sickly De Santos - 2024-12-23 09:00>
DEBUG 2024-12-23 20:01:31,958 base 15672 4972 Exception while resolving variable 'reason' in template 'secretary_dash/doctor/dashboard.html'.
Traceback (most recent call last):
  File "C:\Python312\Lib\site-packages\django\template\base.py", line 883, in _resolve_lookup
    current = current[bit]
              ~~~~~~~^^^^^
TypeError: 'Appointment' object is not subscriptable

During handling of the above exception, another exception occurred:

Traceback (most recent call last):
  File "C:\Python312\Lib\site-packages\django\template\base.py", line 893, in _resolve_lookup
    current = getattr(current, bit)
              ^^^^^^^^^^^^^^^^^^^^^
AttributeError: 'Appointment' object has no attribute 'reason'

During handling of the above exception, another exception occurred:

Traceback (most recent call last):
  File "C:\Python312\Lib\site-packages\django\template\base.py", line 899, in _resolve_lookup
    current = current[int(bit)]
                      ^^^^^^^^
ValueError: invalid literal for int() with base 10: 'reason'

During handling of the above exception, another exception occurred:

Traceback (most recent call last):
  File "C:\Python312\Lib\site-packages\django\template\base.py", line 906, in _resolve_lookup
    raise VariableDoesNotExist(
django.template.base.VariableDoesNotExist: Failed lookup for key [reason] in <Appointment: Sickly De Santos - 2024-12-23 09:00>
DEBUG 2024-12-23 20:01:31,959 base 15672 4972 Exception while resolving variable 'reason' in template 'secretary_dash/doctor/dashboard.html'.
Traceback (most recent call last):
  File "C:\Python312\Lib\site-packages\django\template\base.py", line 883, in _resolve_lookup
    current = current[bit]
              ~~~~~~~^^^^^
TypeError: 'Appointment' object is not subscriptable

During handling of the above exception, another exception occurred:

Traceback (most recent call last):
  File "C:\Python312\Lib\site-packages\django\template\base.py", line 893, in _resolve_lookup
    current = getattr(current, bit)
              ^^^^^^^^^^^^^^^^^^^^^
AttributeError: 'Appointment' object has no attribute 'reason'

During handling of the above exception, another exception occurred:

Traceback (most recent call last):
  File "C:\Python312\Lib\site-packages\django\template\base.py", line 899, in _resolve_lookup
    current = current[int(bit)]
                      ^^^^^^^^
ValueError: invalid literal for int() with base 10: 'reason'

During handling of the above exception, another exception occurred:

Traceback (most recent call last):
  File "C:\Python312\Lib\site-packages\django\template\base.py", line 906, in _resolve_lookup
    raise VariableDoesNotExist(
django.template.base.VariableDoesNotExist: Failed lookup for key [reason] in <Appointment: John doe - 2024-12-23 10:30>
DEBUG 2024-12-23 20:01:31,959 base 15672 4972 Exception while resolving variable 'reason' in template 'secretary_dash/doctor/dashboard.html'.
Traceback (most recent call last):
  File "C:\Python312\Lib\site-packages\django\template\base.py", line 883, in _resolve_lookup
    current = current[bit]
              ~~~~~~~^^^^^
TypeError: 'Appointment' object is not subscriptable

During handling of the above exception, another exception occurred:

Traceback (most recent call last):
  File "C:\Python312\Lib\site-packages\django\template\base.py", line 893, in _resolve_lookup
    current = getattr(current, bit)
              ^^^^^^^^^^^^^^^^^^^^^
AttributeError: 'Appointment' object has no attribute 'reason'

During handling of the above exception, another exception occurred:

Traceback (most recent call last):
  File "C:\Python312\Lib\site-packages\django\template\base.py", line 899, in _resolve_lookup
    current = current[int(bit)]
                      ^^^^^^^^
ValueError: invalid literal for int() with base 10: 'reason'

During handling of the above exception, another exception occurred:

Traceback (most recent call last):
  File "C:\Python312\Lib\site-packages\django\template\base.py", line 906, in _resolve_lookup
    raise VariableDoesNotExist(
django.template.base.VariableDoesNotExist: Failed lookup for key [reason] in <Appointment: John doe - 2024-12-23 10:30>
DEBUG 2024-12-23 20:01:31,961 base 15672 4972 Exception while resolving variable 'reason' in template 'secretary_dash/doctor/dashboard.html'.
Traceback (most recent call last):
  File "C:\Python312\Lib\site-packages\django\template\base.py", line 883, in _resolve_lookup
    current = current[bit]
              ~~~~~~~^^^^^
TypeError: 'Appointment' object is not subscriptable

During handling of the above exception, another exception occurred:

Traceback (most recent call last):
  File "C:\Python312\Lib\site-packages\django\template\base.py", line 893, in _resolve_lookup
    current = getattr(current, bit)
              ^^^^^^^^^^^^^^^^^^^^^
AttributeError: 'Appointment' object has no attribute 'reason'

During handling of the above exception, another exception occurred:

Traceback (most recent call last):
  File "C:\Python312\Lib\site-packages\django\template\base.py", line 899, in _resolve_lookup
    current = current[int(bit)]
                      ^^^^^^^^
ValueError: invalid literal for int() with base 10: 'reason'

During handling of the above exception, another exception occurred:

Traceback (most recent call last):
  File "C:\Python312\Lib\site-packages\django\template\base.py", line 906, in _resolve_lookup
    raise VariableDoesNotExist(
django.template.base.VariableDoesNotExist: Failed lookup for key [reason] in <Appointment: psyc D. mann - 2024-12-23 12:00>
DEBUG 2024-12-23 20:01:31,961 base 15672 4972 Exception while resolving variable 'reason' in template 'secretary_dash/doctor/dashboard.html'.
Traceback (most recent call last):
  File "C:\Python312\Lib\site-packages\django\template\base.py", line 883, in _resolve_lookup
    current = current[bit]
              ~~~~~~~^^^^^
TypeError: 'Appointment' object is not subscriptable

During handling of the above exception, another exception occurred:

Traceback (most recent call last):
  File "C:\Python312\Lib\site-packages\django\template\base.py", line 893, in _resolve_lookup
    current = getattr(current, bit)
              ^^^^^^^^^^^^^^^^^^^^^
AttributeError: 'Appointment' object has no attribute 'reason'

During handling of the above exception, another exception occurred:

Traceback (most recent call last):
  File "C:\Python312\Lib\site-packages\django\template\base.py", line 899, in _resolve_lookup
    current = current[int(bit)]
                      ^^^^^^^^
ValueError: invalid literal for int() with base 10: 'reason'

During handling of the above exception, another exception occurred:

Traceback (most recent call last):
  File "C:\Python312\Lib\site-packages\django\template\base.py", line 906, in _resolve_lookup
    raise VariableDoesNotExist(
django.template.base.VariableDoesNotExist: Failed lookup for key [reason] in <Appointment: psyc D. mann - 2024-12-23 12:00>
DEBUG 2024-12-23 20:01:31,962 base 15672 4972 Exception while resolving variable 'reason' in template 'secretary_dash/doctor/dashboard.html'.
Traceback (most recent call last):
  File "C:\Python312\Lib\site-packages\django\template\base.py", line 883, in _resolve_lookup
    current = current[bit]
              ~~~~~~~^^^^^
TypeError: 'Appointment' object is not subscriptable

During handling of the above exception, another exception occurred:

Traceback (most recent call last):
  File "C:\Python312\Lib\site-packages\django\template\base.py", line 893, in _resolve_lookup
    current = getattr(current, bit)
              ^^^^^^^^^^^^^^^^^^^^^
AttributeError: 'Appointment' object has no attribute 'reason'

During handling of the above exception, another exception occurred:

Traceback (most recent call last):
  File "C:\Python312\Lib\site-packages\django\template\base.py", line 899, in _resolve_lookup
    current = current[int(bit)]
                      ^^^^^^^^
ValueError: invalid literal for int() with base 10: 'reason'

During handling of the above exception, another exception occurred:

Traceback (most recent call last):
  File "C:\Python312\Lib\site-packages\django\template\base.py", line 906, in _resolve_lookup
    raise VariableDoesNotExist(
django.template.base.VariableDoesNotExist: Failed lookup for key [reason] in <Appointment: psyc D. mann - 2024-12-23 14:00>
DEBUG 2024-12-23 20:01:31,962 base 15672 4972 Exception while resolving variable 'reason' in template 'secretary_dash/doctor/dashboard.html'.
Traceback (most recent call last):
  File "C:\Python312\Lib\site-packages\django\template\base.py", line 883, in _resolve_lookup
    current = current[bit]
              ~~~~~~~^^^^^
TypeError: 'Appointment' object is not subscriptable

During handling of the above exception, another exception occurred:

Traceback (most recent call last):
  File "C:\Python312\Lib\site-packages\django\template\base.py", line 893, in _resolve_lookup
    current = getattr(current, bit)
              ^^^^^^^^^^^^^^^^^^^^^
AttributeError: 'Appointment' object has no attribute 'reason'

During handling of the above exception, another exception occurred:

Traceback (most recent call last):
  File "C:\Python312\Lib\site-packages\django\template\base.py", line 899, in _resolve_lookup
    current = current[int(bit)]
                      ^^^^^^^^
ValueError: invalid literal for int() with base 10: 'reason'

During handling of the above exception, another exception occurred:

Traceback (most recent call last):
  File "C:\Python312\Lib\site-packages\django\template\base.py", line 906, in _resolve_lookup
    raise VariableDoesNotExist(
django.template.base.VariableDoesNotExist: Failed lookup for key [reason] in <Appointment: psyc D. mann - 2024-12-23 14:00>
DEBUG 2024-12-23 20:01:31,963 base 15672 4972 Exception while resolving variable 'reason' in template 'secretary_dash/doctor/dashboard.html'.
Traceback (most recent call last):
  File "C:\Python312\Lib\site-packages\django\template\base.py", line 883, in _resolve_lookup
    current = current[bit]
              ~~~~~~~^^^^^
TypeError: 'Appointment' object is not subscriptable

During handling of the above exception, another exception occurred:

Traceback (most recent call last):
  File "C:\Python312\Lib\site-packages\django\template\base.py", line 893, in _resolve_lookup
    current = getattr(current, bit)
              ^^^^^^^^^^^^^^^^^^^^^
AttributeError: 'Appointment' object has no attribute 'reason'

During handling of the above exception, another exception occurred:

Traceback (most recent call last):
  File "C:\Python312\Lib\site-packages\django\template\base.py", line 899, in _resolve_lookup
    current = current[int(bit)]
                      ^^^^^^^^
ValueError: invalid literal for int() with base 10: 'reason'

During handling of the above exception, another exception occurred:

Traceback (most recent call last):
  File "C:\Python312\Lib\site-packages\django\template\base.py", line 906, in _resolve_lookup
    raise VariableDoesNotExist(
django.template.base.VariableDoesNotExist: Failed lookup for key [reason] in <Appointment: Corey V. Depen - 2024-12-23 16:00>
DEBUG 2024-12-23 20:01:31,963 base 15672 4972 Exception while resolving variable 'reason' in template 'secretary_dash/doctor/dashboard.html'.
Traceback (most recent call last):
  File "C:\Python312\Lib\site-packages\django\template\base.py", line 883, in _resolve_lookup
    current = current[bit]
              ~~~~~~~^^^^^
TypeError: 'Appointment' object is not subscriptable

During handling of the above exception, another exception occurred:

Traceback (most recent call last):
  File "C:\Python312\Lib\site-packages\django\template\base.py", line 893, in _resolve_lookup
    current = getattr(current, bit)
              ^^^^^^^^^^^^^^^^^^^^^
AttributeError: 'Appointment' object has no attribute 'reason'

During handling of the above exception, another exception occurred:

Traceback (most recent call last):
  File "C:\Python312\Lib\site-packages\django\template\base.py", line 899, in _resolve_lookup
    current = current[int(bit)]
                      ^^^^^^^^
ValueError: invalid literal for int() with base 10: 'reason'

During handling of the above exception, another exception occurred:

Traceback (most recent call last):
  File "C:\Python312\Lib\site-packages\django\template\base.py", line 906, in _resolve_lookup
    raise VariableDoesNotExist(
django.template.base.VariableDoesNotExist: Failed lookup for key [reason] in <Appointment: Corey V. Depen - 2024-12-23 16:00>
INFO 2024-12-23 20:01:31,964 basehttp 15672 4972 "GET /doctor/ HTTP/1.1" 200 33508
INFO 2024-12-23 20:02:32,692 basehttp 15672 4972 "GET /medicines/ HTTP/1.1" 200 3752
INFO 2024-12-23 20:02:39,414 basehttp 15672 4972 "GET /medicines/ HTTP/1.1" 200 3752
INFO 2024-12-23 20:02:40,792 basehttp 15672 4972 "GET /patients/ HTTP/1.1" 200 3752
INFO 2024-12-23 20:02:48,771 basehttp 15672 4972 "GET /patients/ HTTP/1.1" 200 3752
INFO 2024-12-23 20:03:15,282 basehttp 15672 4972 "GET /examinations/ HTTP/1.1" 200 3752
INFO 2024-12-23 20:03:16,979 basehttp 15672 4972 "GET /examinations/ HTTP/1.1" 200 3752
INFO 2024-12-23 20:04:14,013 basehttp 15672 4972 "GET /examinations/ HTTP/1.1" 200 3752
INFO 2024-12-23 20:04:15,651 basehttp 15672 4972 "GET /patients/ HTTP/1.1" 200 3752
INFO 2024-12-23 20:04:49,200 basehttp 15672 4972 "GET /patients/ HTTP/1.1" 200 11564
INFO 2024-12-23 20:04:50,259 basehttp 15672 4972 "GET /medicines/ HTTP/1.1" 200 8526
INFO 2024-12-23 20:04:50,838 basehttp 15672 4972 "GET /appointments/ HTTP/1.1" 200 12867
DEBUG 2024-12-23 20:04:53,350 base 15672 4972 Exception while resolving variable 'is_completed' in template 'secretary_dash/doctor/examination_list.html'.
Traceback (most recent call last):
  File "C:\Python312\Lib\site-packages\django\template\base.py", line 883, in _resolve_lookup
    current = current[bit]
              ~~~~~~~^^^^^
TypeError: 'Examination' object is not subscriptable

During handling of the above exception, another exception occurred:

Traceback (most recent call last):
  File "C:\Python312\Lib\site-packages\django\template\base.py", line 893, in _resolve_lookup
    current = getattr(current, bit)
              ^^^^^^^^^^^^^^^^^^^^^
AttributeError: 'Examination' object has no attribute 'is_completed'

During handling of the above exception, another exception occurred:

Traceback (most recent call last):
  File "C:\Python312\Lib\site-packages\django\template\base.py", line 899, in _resolve_lookup
    current = current[int(bit)]
                      ^^^^^^^^
ValueError: invalid literal for int() with base 10: 'is_completed'

During handling of the above exception, another exception occurred:

Traceback (most recent call last):
  File "C:\Python312\Lib\site-packages\django\template\base.py", line 906, in _resolve_lookup
    raise VariableDoesNotExist(
django.template.base.VariableDoesNotExist: Failed lookup for key [is_completed] in <Examination: Examination for psyc D. mann on 2024-12-23>
DEBUG 2024-12-23 20:04:53,350 base 15672 4972 Exception while resolving variable 'is_completed' in template 'secretary_dash/doctor/examination_list.html'.
Traceback (most recent call last):
  File "C:\Python312\Lib\site-packages\django\template\base.py", line 883, in _resolve_lookup
    current = current[bit]
              ~~~~~~~^^^^^
TypeError: 'Examination' object is not subscriptable

During handling of the above exception, another exception occurred:

Traceback (most recent call last):
  File "C:\Python312\Lib\site-packages\django\template\base.py", line 893, in _resolve_lookup
    current = getattr(current, bit)
              ^^^^^^^^^^^^^^^^^^^^^
AttributeError: 'Examination' object has no attribute 'is_completed'

During handling of the above exception, another exception occurred:

Traceback (most recent call last):
  File "C:\Python312\Lib\site-packages\django\template\base.py", line 899, in _resolve_lookup
    current = current[int(bit)]
                      ^^^^^^^^
ValueError: invalid literal for int() with base 10: 'is_completed'

During handling of the above exception, another exception occurred:

Traceback (most recent call last):
  File "C:\Python312\Lib\site-packages\django\template\base.py", line 906, in _resolve_lookup
    raise VariableDoesNotExist(
django.template.base.VariableDoesNotExist: Failed lookup for key [is_completed] in <Examination: Examination for psyc D. mann on 2024-12-23>
DEBUG 2024-12-23 20:04:53,355 base 15672 4972 Exception while resolving variable 'is_completed' in template 'secretary_dash/doctor/examination_list.html'.
Traceback (most recent call last):
  File "C:\Python312\Lib\site-packages\django\template\base.py", line 883, in _resolve_lookup
    current = current[bit]
              ~~~~~~~^^^^^
TypeError: 'Examination' object is not subscriptable

During handling of the above exception, another exception occurred:

Traceback (most recent call last):
  File "C:\Python312\Lib\site-packages\django\template\base.py", line 893, in _resolve_lookup
    current = getattr(current, bit)
              ^^^^^^^^^^^^^^^^^^^^^
AttributeError: 'Examination' object has no attribute 'is_completed'

During handling of the above exception, another exception occurred:

Traceback (most recent call last):
  File "C:\Python312\Lib\site-packages\django\template\base.py", line 899, in _resolve_lookup
    current = current[int(bit)]
                      ^^^^^^^^
ValueError: invalid literal for int() with base 10: 'is_completed'

During handling of the above exception, another exception occurred:

Traceback (most recent call last):
  File "C:\Python312\Lib\site-packages\django\template\base.py", line 906, in _resolve_lookup
    raise VariableDoesNotExist(
django.template.base.VariableDoesNotExist: Failed lookup for key [is_completed] in <Examination: Examination for Sickly De Santos on 2024-12-23>
DEBUG 2024-12-23 20:04:53,355 base 15672 4972 Exception while resolving variable 'is_completed' in template 'secretary_dash/doctor/examination_list.html'.
Traceback (most recent call last):
  File "C:\Python312\Lib\site-packages\django\template\base.py", line 883, in _resolve_lookup
    current = current[bit]
              ~~~~~~~^^^^^
TypeError: 'Examination' object is not subscriptable

During handling of the above exception, another exception occurred:

Traceback (most recent call last):
  File "C:\Python312\Lib\site-packages\django\template\base.py", line 893, in _resolve_lookup
    current = getattr(current, bit)
              ^^^^^^^^^^^^^^^^^^^^^
AttributeError: 'Examination' object has no attribute 'is_completed'

During handling of the above exception, another exception occurred:

Traceback (most recent call last):
  File "C:\Python312\Lib\site-packages\django\template\base.py", line 899, in _resolve_lookup
    current = current[int(bit)]
                      ^^^^^^^^
ValueError: invalid literal for int() with base 10: 'is_completed'

During handling of the above exception, another exception occurred:

Traceback (most recent call last):
  File "C:\Python312\Lib\site-packages\django\template\base.py", line 906, in _resolve_lookup
    raise VariableDoesNotExist(
django.template.base.VariableDoesNotExist: Failed lookup for key [is_completed] in <Examination: Examination for Sickly De Santos on 2024-12-23>
DEBUG 2024-12-23 20:04:53,358 base 15672 4972 Exception while resolving variable 'is_completed' in template 'secretary_dash/doctor/examination_list.html'.
Traceback (most recent call last):
  File "C:\Python312\Lib\site-packages\django\template\base.py", line 883, in _resolve_lookup
    current = current[bit]
              ~~~~~~~^^^^^
TypeError: 'Examination' object is not subscriptable

During handling of the above exception, another exception occurred:

Traceback (most recent call last):
  File "C:\Python312\Lib\site-packages\django\template\base.py", line 893, in _resolve_lookup
    current = getattr(current, bit)
              ^^^^^^^^^^^^^^^^^^^^^
AttributeError: 'Examination' object has no attribute 'is_completed'

During handling of the above exception, another exception occurred:

Traceback (most recent call last):
  File "C:\Python312\Lib\site-packages\django\template\base.py", line 899, in _resolve_lookup
    current = current[int(bit)]
                      ^^^^^^^^
ValueError: invalid literal for int() with base 10: 'is_completed'

During handling of the above exception, another exception occurred:

Traceback (most recent call last):
  File "C:\Python312\Lib\site-packages\django\template\base.py", line 906, in _resolve_lookup
    raise VariableDoesNotExist(
django.template.base.VariableDoesNotExist: Failed lookup for key [is_completed] in <Examination: Examination for John doe on 2024-12-23>
DEBUG 2024-12-23 20:04:53,358 base 15672 4972 Exception while resolving variable 'is_completed' in template 'secretary_dash/doctor/examination_list.html'.
Traceback (most recent call last):
  File "C:\Python312\Lib\site-packages\django\template\base.py", line 883, in _resolve_lookup
    current = current[bit]
              ~~~~~~~^^^^^
TypeError: 'Examination' object is not subscriptable

During handling of the above exception, another exception occurred:

Traceback (most recent call last):
  File "C:\Python312\Lib\site-packages\django\template\base.py", line 893, in _resolve_lookup
    current = getattr(current, bit)
              ^^^^^^^^^^^^^^^^^^^^^
AttributeError: 'Examination' object has no attribute 'is_completed'

During handling of the above exception, another exception occurred:

Traceback (most recent call last):
  File "C:\Python312\Lib\site-packages\django\template\base.py", line 899, in _resolve_lookup
    current = current[int(bit)]
                      ^^^^^^^^
ValueError: invalid literal for int() with base 10: 'is_completed'

During handling of the above exception, another exception occurred:

Traceback (most recent call last):
  File "C:\Python312\Lib\site-packages\django\template\base.py", line 906, in _resolve_lookup
    raise VariableDoesNotExist(
django.template.base.VariableDoesNotExist: Failed lookup for key [is_completed] in <Examination: Examination for John doe on 2024-12-23>
DEBUG 2024-12-23 20:04:53,361 base 15672 4972 Exception while resolving variable 'is_completed' in template 'secretary_dash/doctor/examination_list.html'.
Traceback (most recent call last):
  File "C:\Python312\Lib\site-packages\django\template\base.py", line 883, in _resolve_lookup
    current = current[bit]
              ~~~~~~~^^^^^
TypeError: 'Examination' object is not subscriptable

During handling of the above exception, another exception occurred:

Traceback (most recent call last):
  File "C:\Python312\Lib\site-packages\django\template\base.py", line 893, in _resolve_lookup
    current = getattr(current, bit)
              ^^^^^^^^^^^^^^^^^^^^^
AttributeError: 'Examination' object has no attribute 'is_completed'

During handling of the above exception, another exception occurred:

Traceback (most recent call last):
  File "C:\Python312\Lib\site-packages\django\template\base.py", line 899, in _resolve_lookup
    current = current[int(bit)]
                      ^^^^^^^^
ValueError: invalid literal for int() with base 10: 'is_completed'

During handling of the above exception, another exception occurred:

Traceback (most recent call last):
  File "C:\Python312\Lib\site-packages\django\template\base.py", line 906, in _resolve_lookup
    raise VariableDoesNotExist(
django.template.base.VariableDoesNotExist: Failed lookup for key [is_completed] in <Examination: Examination for psyc D. mann on 2024-12-22>
DEBUG 2024-12-23 20:04:53,361 base 15672 4972 Exception while resolving variable 'is_completed' in template 'secretary_dash/doctor/examination_list.html'.
Traceback (most recent call last):
  File "C:\Python312\Lib\site-packages\django\template\base.py", line 883, in _resolve_lookup
    current = current[bit]
              ~~~~~~~^^^^^
TypeError: 'Examination' object is not subscriptable

During handling of the above exception, another exception occurred:

Traceback (most recent call last):
  File "C:\Python312\Lib\site-packages\django\template\base.py", line 893, in _resolve_lookup
    current = getattr(current, bit)
              ^^^^^^^^^^^^^^^^^^^^^
AttributeError: 'Examination' object has no attribute 'is_completed'

During handling of the above exception, another exception occurred:

Traceback (most recent call last):
  File "C:\Python312\Lib\site-packages\django\template\base.py", line 899, in _resolve_lookup
    current = current[int(bit)]
                      ^^^^^^^^
ValueError: invalid literal for int() with base 10: 'is_completed'

During handling of the above exception, another exception occurred:

Traceback (most recent call last):
  File "C:\Python312\Lib\site-packages\django\template\base.py", line 906, in _resolve_lookup
    raise VariableDoesNotExist(
django.template.base.VariableDoesNotExist: Failed lookup for key [is_completed] in <Examination: Examination for psyc D. mann on 2024-12-22>
INFO 2024-12-23 20:04:53,364 basehttp 15672 4972 "GET /examinations/ HTTP/1.1" 200 11698
INFO 2024-12-23 20:04:54,227 basehttp 15672 4972 "POST /logout/ HTTP/1.1" 302 0
INFO 2024-12-23 20:04:54,233 basehttp 15672 4972 "GET /login/ HTTP/1.1" 200 4979
INFO 2024-12-23 20:04:57,185 basehttp 15672 4972 "POST /login/ HTTP/1.1" 302 0
INFO 2024-12-23 20:04:57,193 basehttp 15672 4972 "GET / HTTP/1.1" 302 0
INFO 2024-12-23 20:04:57,221 basehttp 15672 4972 "GET /secretary/ HTTP/1.1" 200 27462
INFO 2024-12-23 20:06:20,293 basehttp 15672 4972 "GET /secretary/ HTTP/1.1" 200 27462
INFO 2024-12-23 20:06:41,853 basehttp 15672 4972 "GET /secretary/ HTTP/1.1" 200 27462
INFO 2024-12-23 20:06:57,410 basehttp 15672 4972 "GET /secretary/ HTTP/1.1" 200 27462
INFO 2024-12-23 20:07:04,968 basehttp 15672 4972 "GET /secretary/ HTTP/1.1" 200 27462
INFO 2024-12-23 20:07:14,161 basehttp 15672 4972 "GET /secretary/ HTTP/1.1" 200 27462
INFO 2024-12-23 20:08:35,585 basehttp 15672 4972 "GET /secretary/ HTTP/1.1" 200 27462
INFO 2024-12-23 20:09:36,718 basehttp 15672 4972 "GET /secretary/ HTTP/1.1" 200 27462
INFO 2024-12-23 20:10:35,097 basehttp 15672 4972 "GET /secretary/ HTTP/1.1" 200 27462
INFO 2024-12-23 20:11:51,537 basehttp 15672 4972 "GET /secretary/ HTTP/1.1" 200 27462
INFO 2024-12-23 20:13:28,712 basehttp 15672 4972 "GET /secretary/ HTTP/1.1" 200 27462
INFO 2024-12-23 20:14:41,183 basehttp 15672 4972 "GET /secretary/ HTTP/1.1" 200 27462
INFO 2024-12-23 20:17:53,926 basehttp 15672 4972 "GET /secretary/ HTTP/1.1" 200 27466
INFO 2024-12-23 20:18:01,060 basehttp 15672 4972 "GET /secretary/ HTTP/1.1" 200 27462
INFO 2024-12-23 20:19:28,102 basehttp 15672 4972 "GET /secretary/ HTTP/1.1" 200 27462
INFO 2024-12-23 20:19:34,785 basehttp 15672 4972 "GET /secretary/ HTTP/1.1" 200 27462
INFO 2024-12-23 20:22:53,370 autoreload 15672 1772 C:\Users\DC\Desktop\itec320_project20801530\itec320_project20801530\Itec320_project\secretary_dash\views.py changed, reloading.
INFO 2024-12-23 20:22:53,988 autoreload 18664 1752 Watching for file changes with StatReloader
INFO 2024-12-23 20:23:07,514 autoreload 18664 1752 C:\Users\DC\Desktop\itec320_project20801530\itec320_project20801530\Itec320_project\secretary_dash\views.py changed, reloading.
INFO 2024-12-23 20:23:08,024 autoreload 1476 19152 Watching for file changes with StatReloader
INFO 2024-12-23 20:23:10,248 autoreload 1476 19152 C:\Users\DC\Desktop\itec320_project20801530\itec320_project20801530\Itec320_project\secretary_dash\views.py changed, reloading.
INFO 2024-12-23 20:23:10,702 autoreload 5064 10952 Watching for file changes with StatReloader
INFO 2024-12-23 20:23:12,928 autoreload 5064 10952 C:\Users\DC\Desktop\itec320_project20801530\itec320_project20801530\Itec320_project\secretary_dash\views.py changed, reloading.
INFO 2024-12-23 20:23:13,458 autoreload 19536 4532 Watching for file changes with StatReloader
INFO 2024-12-23 20:23:15,722 autoreload 19536 4532 C:\Users\DC\Desktop\itec320_project20801530\itec320_project20801530\Itec320_project\secretary_dash\views.py changed, reloading.
INFO 2024-12-23 20:23:16,163 autoreload 13624 17008 Watching for file changes with StatReloader
INFO 2024-12-23 20:27:25,899 basehttp 13624 18928 "POST /logout/ HTTP/1.1" 302 0
INFO 2024-12-23 20:27:25,912 basehttp 13624 18928 "GET /login/ HTTP/1.1" 200 4979
INFO 2024-12-23 20:27:30,904 basehttp 13624 18928 "POST /login/ HTTP/1.1" 200 5181
INFO 2024-12-23 20:27:35,040 basehttp 13624 18928 "POST /login/ HTTP/1.1" 302 0
INFO 2024-12-23 20:27:35,047 basehttp 13624 18928 "GET / HTTP/1.1" 302 0
DEBUG 2024-12-23 20:27:35,099 base 13624 18928 Exception while resolving variable 'reason' in template 'secretary_dash/doctor/dashboard.html'.
Traceback (most recent call last):
  File "C:\Python312\Lib\site-packages\django\template\base.py", line 883, in _resolve_lookup
    current = current[bit]
              ~~~~~~~^^^^^
TypeError: 'Appointment' object is not subscriptable

During handling of the above exception, another exception occurred:

Traceback (most recent call last):
  File "C:\Python312\Lib\site-packages\django\template\base.py", line 893, in _resolve_lookup
    current = getattr(current, bit)
              ^^^^^^^^^^^^^^^^^^^^^
AttributeError: 'Appointment' object has no attribute 'reason'

During handling of the above exception, another exception occurred:

Traceback (most recent call last):
  File "C:\Python312\Lib\site-packages\django\template\base.py", line 899, in _resolve_lookup
    current = current[int(bit)]
                      ^^^^^^^^
ValueError: invalid literal for int() with base 10: 'reason'

During handling of the above exception, another exception occurred:

Traceback (most recent call last):
  File "C:\Python312\Lib\site-packages\django\template\base.py", line 906, in _resolve_lookup
    raise VariableDoesNotExist(
django.template.base.VariableDoesNotExist: Failed lookup for key [reason] in <Appointment: Sickly De Santos - 2024-12-23 09:00>
DEBUG 2024-12-23 20:27:35,099 base 13624 18928 Exception while resolving variable 'reason' in template 'secretary_dash/doctor/dashboard.html'.
Traceback (most recent call last):
  File "C:\Python312\Lib\site-packages\django\template\base.py", line 883, in _resolve_lookup
    current = current[bit]
              ~~~~~~~^^^^^
TypeError: 'Appointment' object is not subscriptable

During handling of the above exception, another exception occurred:

Traceback (most recent call last):
  File "C:\Python312\Lib\site-packages\django\template\base.py", line 893, in _resolve_lookup
    current = getattr(current, bit)
              ^^^^^^^^^^^^^^^^^^^^^
AttributeError: 'Appointment' object has no attribute 'reason'

During handling of the above exception, another exception occurred:

Traceback (most recent call last):
  File "C:\Python312\Lib\site-packages\django\template\base.py", line 899, in _resolve_lookup
    current = current[int(bit)]
                      ^^^^^^^^
ValueError: invalid literal for int() with base 10: 'reason'

During handling of the above exception, another exception occurred:

Traceback (most recent call last):
  File "C:\Python312\Lib\site-packages\django\template\base.py", line 906, in _resolve_lookup
    raise VariableDoesNotExist(
django.template.base.VariableDoesNotExist: Failed lookup for key [reason] in <Appointment: Sickly De Santos - 2024-12-23 09:00>
DEBUG 2024-12-23 20:27:35,124 base 13624 18928 Exception while resolving variable 'reason' in template 'secretary_dash/doctor/dashboard.html'.
Traceback (most recent call last):
  File "C:\Python312\Lib\site-packages\django\template\base.py", line 883, in _resolve_lookup
    current = current[bit]
              ~~~~~~~^^^^^
TypeError: 'Appointment' object is not subscriptable

During handling of the above exception, another exception occurred:

Traceback (most recent call last):
  File "C:\Python312\Lib\site-packages\django\template\base.py", line 893, in _resolve_lookup
    current = getattr(current, bit)
              ^^^^^^^^^^^^^^^^^^^^^
AttributeError: 'Appointment' object has no attribute 'reason'

During handling of the above exception, another exception occurred:

Traceback (most recent call last):
  File "C:\Python312\Lib\site-packages\django\template\base.py", line 899, in _resolve_lookup
    current = current[int(bit)]
                      ^^^^^^^^
ValueError: invalid literal for int() with base 10: 'reason'

During handling of the above exception, another exception occurred:

Traceback (most recent call last):
  File "C:\Python312\Lib\site-packages\django\template\base.py", line 906, in _resolve_lookup
    raise VariableDoesNotExist(
django.template.base.VariableDoesNotExist: Failed lookup for key [reason] in <Appointment: John doe - 2024-12-23 10:30>
DEBUG 2024-12-23 20:27:35,124 base 13624 18928 Exception while resolving variable 'reason' in template 'secretary_dash/doctor/dashboard.html'.
Traceback (most recent call last):
  File "C:\Python312\Lib\site-packages\django\template\base.py", line 883, in _resolve_lookup
    current = current[bit]
              ~~~~~~~^^^^^
TypeError: 'Appointment' object is not subscriptable

During handling of the above exception, another exception occurred:

Traceback (most recent call last):
  File "C:\Python312\Lib\site-packages\django\template\base.py", line 893, in _resolve_lookup
    current = getattr(current, bit)
              ^^^^^^^^^^^^^^^^^^^^^
AttributeError: 'Appointment' object has no attribute 'reason'

During handling of the above exception, another exception occurred:

Traceback (most recent call last):
  File "C:\Python312\Lib\site-packages\django\template\base.py", line 899, in _resolve_lookup
    current = current[int(bit)]
                      ^^^^^^^^
ValueError: invalid literal for int() with base 10: 'reason'

During handling of the above exception, another exception occurred:

Traceback (most recent call last):
  File "C:\Python312\Lib\site-packages\django\template\base.py", line 906, in _resolve_lookup
    raise VariableDoesNotExist(
django.template.base.VariableDoesNotExist: Failed lookup for key [reason] in <Appointment: John doe - 2024-12-23 10:30>
DEBUG 2024-12-23 20:27:35,127 base 13624 18928 Exception while resolving variable 'reason' in template 'secretary_dash/doctor/dashboard.html'.
Traceback (most recent call last):
  File "C:\Python312\Lib\site-packages\django\template\base.py", line 883, in _resolve_lookup
    current = current[bit]
              ~~~~~~~^^^^^
TypeError: 'Appointment' object is not subscriptable

During handling of the above exception, another exception occurred:

Traceback (most recent call last):
  File "C:\Python312\Lib\site-packages\django\template\base.py", line 893, in _resolve_lookup
    current = getattr(current, bit)
              ^^^^^^^^^^^^^^^^^^^^^
AttributeError: 'Appointment' object has no attribute 'reason'

During handling of the above exception, another exception occurred:

Traceback (most recent call last):
  File "C:\Python312\Lib\site-packages\django\template\base.py", line 899, in _resolve_lookup
    current = current[int(bit)]
                      ^^^^^^^^
ValueError: invalid literal for int() with base 10: 'reason'

During handling of the above exception, another exception occurred:

Traceback (most recent call last):
  File "C:\Python312\Lib\site-packages\django\template\base.py", line 906, in _resolve_lookup
    raise VariableDoesNotExist(
django.template.base.VariableDoesNotExist: Failed lookup for key [reason] in <Appointment: psyc D. mann - 2024-12-23 12:00>
DEBUG 2024-12-23 20:27:35,127 base 13624 18928 Exception while resolving variable 'reason' in template 'secretary_dash/doctor/dashboard.html'.
Traceback (most recent call last):
  File "C:\Python312\Lib\site-packages\django\template\base.py", line 883, in _resolve_lookup
    current = current[bit]
              ~~~~~~~^^^^^
TypeError: 'Appointment' object is not subscriptable

During handling of the above exception, another exception occurred:

Traceback (most recent call last):
  File "C:\Python312\Lib\site-packages\django\template\base.py", line 893, in _resolve_lookup
    current = getattr(current, bit)
              ^^^^^^^^^^^^^^^^^^^^^
AttributeError: 'Appointment' object has no attribute 'reason'

During handling of the above exception, another exception occurred:

Traceback (most recent call last):
  File "C:\Python312\Lib\site-packages\django\template\base.py", line 899, in _resolve_lookup
    current = current[int(bit)]
                      ^^^^^^^^
ValueError: invalid literal for int() with base 10: 'reason'

During handling of the above exception, another exception occurred:

Traceback (most recent call last):
  File "C:\Python312\Lib\site-packages\django\template\base.py", line 906, in _resolve_lookup
    raise VariableDoesNotExist(
django.template.base.VariableDoesNotExist: Failed lookup for key [reason] in <Appointment: psyc D. mann - 2024-12-23 12:00>
DEBUG 2024-12-23 20:27:35,129 base 13624 18928 Exception while resolving variable 'reason' in template 'secretary_dash/doctor/dashboard.html'.
Traceback (most recent call last):
  File "C:\Python312\Lib\site-packages\django\template\base.py", line 883, in _resolve_lookup
    current = current[bit]
              ~~~~~~~^^^^^
TypeError: 'Appointment' object is not subscriptable

During handling of the above exception, another exception occurred:

Traceback (most recent call last):
  File "C:\Python312\Lib\site-packages\django\template\base.py", line 893, in _resolve_lookup
    current = getattr(current, bit)
              ^^^^^^^^^^^^^^^^^^^^^
AttributeError: 'Appointment' object has no attribute 'reason'

During handling of the above exception, another exception occurred:

Traceback (most recent call last):
  File "C:\Python312\Lib\site-packages\django\template\base.py", line 899, in _resolve_lookup
    current = current[int(bit)]
                      ^^^^^^^^
ValueError: invalid literal for int() with base 10: 'reason'

During handling of the above exception, another exception occurred:

Traceback (most recent call last):
  File "C:\Python312\Lib\site-packages\django\template\base.py", line 906, in _resolve_lookup
    raise VariableDoesNotExist(
django.template.base.VariableDoesNotExist: Failed lookup for key [reason] in <Appointment: psyc D. mann - 2024-12-23 14:00>
DEBUG 2024-12-23 20:27:35,129 base 13624 18928 Exception while resolving variable 'reason' in template 'secretary_dash/doctor/dashboard.html'.
Traceback (most recent call last):
  File "C:\Python312\Lib\site-packages\django\template\base.py", line 883, in _resolve_lookup
    current = current[bit]
              ~~~~~~~^^^^^
TypeError: 'Appointment' object is not subscriptable

During handling of the above exception, another exception occurred:

Traceback (most recent call last):
  File "C:\Python312\Lib\site-packages\django\template\base.py", line 893, in _resolve_lookup
    current = getattr(current, bit)
              ^^^^^^^^^^^^^^^^^^^^^
AttributeError: 'Appointment' object has no attribute 'reason'

During handling of the above exception, another exception occurred:

Traceback (most recent call last):
  File "C:\Python312\Lib\site-packages\django\template\base.py", line 899, in _resolve_lookup
    current = current[int(bit)]
                      ^^^^^^^^
ValueError: invalid literal for int() with base 10: 'reason'

During handling of the above exception, another exception occurred:

Traceback (most recent call last):
  File "C:\Python312\Lib\site-packages\django\template\base.py", line 906, in _resolve_lookup
    raise VariableDoesNotExist(
django.template.base.VariableDoesNotExist: Failed lookup for key [reason] in <Appointment: psyc D. mann - 2024-12-23 14:00>
DEBUG 2024-12-23 20:27:35,131 base 13624 18928 Exception while resolving variable 'reason' in template 'secretary_dash/doctor/dashboard.html'.
Traceback (most recent call last):
  File "C:\Python312\Lib\site-packages\django\template\base.py", line 883, in _resolve_lookup
    current = current[bit]
              ~~~~~~~^^^^^
TypeError: 'Appointment' object is not subscriptable

During handling of the above exception, another exception occurred:

Traceback (most recent call last):
  File "C:\Python312\Lib\site-packages\django\template\base.py", line 893, in _resolve_lookup
    current = getattr(current, bit)
              ^^^^^^^^^^^^^^^^^^^^^
AttributeError: 'Appointment' object has no attribute 'reason'

During handling of the above exception, another exception occurred:

Traceback (most recent call last):
  File "C:\Python312\Lib\site-packages\django\template\base.py", line 899, in _resolve_lookup
    current = current[int(bit)]
                      ^^^^^^^^
ValueError: invalid literal for int() with base 10: 'reason'

During handling of the above exception, another exception occurred:

Traceback (most recent call last):
  File "C:\Python312\Lib\site-packages\django\template\base.py", line 906, in _resolve_lookup
    raise VariableDoesNotExist(
django.template.base.VariableDoesNotExist: Failed lookup for key [reason] in <Appointment: Corey V. Depen - 2024-12-23 16:00>
DEBUG 2024-12-23 20:27:35,131 base 13624 18928 Exception while resolving variable 'reason' in template 'secretary_dash/doctor/dashboard.html'.
Traceback (most recent call last):
  File "C:\Python312\Lib\site-packages\django\template\base.py", line 883, in _resolve_lookup
    current = current[bit]
              ~~~~~~~^^^^^
TypeError: 'Appointment' object is not subscriptable

During handling of the above exception, another exception occurred:

Traceback (most recent call last):
  File "C:\Python312\Lib\site-packages\django\template\base.py", line 893, in _resolve_lookup
    current = getattr(current, bit)
              ^^^^^^^^^^^^^^^^^^^^^
AttributeError: 'Appointment' object has no attribute 'reason'

During handling of the above exception, another exception occurred:

Traceback (most recent call last):
  File "C:\Python312\Lib\site-packages\django\template\base.py", line 899, in _resolve_lookup
    current = current[int(bit)]
                      ^^^^^^^^
ValueError: invalid literal for int() with base 10: 'reason'

During handling of the above exception, another exception occurred:

Traceback (most recent call last):
  File "C:\Python312\Lib\site-packages\django\template\base.py", line 906, in _resolve_lookup
    raise VariableDoesNotExist(
django.template.base.VariableDoesNotExist: Failed lookup for key [reason] in <Appointment: Corey V. Depen - 2024-12-23 16:00>
INFO 2024-12-23 20:27:35,133 basehttp 13624 18928 "GET /doctor/ HTTP/1.1" 200 33508
INFO 2024-12-23 20:27:36,384 basehttp 13624 18928 "GET /doctor/secretaries/ HTTP/1.1" 200 7603
INFO 2024-12-23 20:27:39,954 basehttp 13624 18928 "POST /doctor/secretaries/11/delete/ HTTP/1.1" 302 0
INFO 2024-12-23 20:27:39,966 basehttp 13624 18928 "GET /doctor/secretaries/ HTTP/1.1" 200 6724
INFO 2024-12-23 20:27:41,025 basehttp 13624 18928 "GET /doctor/secretaries/add/ HTTP/1.1" 200 8510
INFO 2024-12-23 20:28:04,656 basehttp 13624 18928 "POST /doctor/secretaries/add/ HTTP/1.1" 302 0
INFO 2024-12-23 20:28:04,667 basehttp 13624 18928 "GET /doctor/secretaries/ HTTP/1.1" 200 8177
INFO 2024-12-23 20:29:13,446 basehttp 13624 18928 "POST /doctor/secretaries/13/delete/ HTTP/1.1" 302 0
INFO 2024-12-23 20:29:13,455 basehttp 13624 18928 "GET /doctor/secretaries/ HTTP/1.1" 200 6724
INFO 2024-12-23 20:29:14,118 basehttp 13624 18928 "GET /doctor/secretaries/add/ HTTP/1.1" 200 8510
INFO 2024-12-23 20:29:36,097 basehttp 13624 18928 "POST /doctor/secretaries/add/ HTTP/1.1" 302 0
INFO 2024-12-23 20:29:36,111 basehttp 13624 18928 "GET /doctor/secretaries/ HTTP/1.1" 200 8175
INFO 2024-12-23 20:46:06,994 autoreload 13540 17468 Watching for file changes with StatReloader
INFO 2024-12-23 20:46:08,341 basehttp 13540 8316 "GET / HTTP/1.1" 302 0
DEBUG 2024-12-23 20:46:08,375 base 13540 8316 Exception while resolving variable 'reason' in template 'secretary_dash/doctor/dashboard.html'.
Traceback (most recent call last):
  File "C:\Python312\Lib\site-packages\django\template\base.py", line 883, in _resolve_lookup
    current = current[bit]
              ~~~~~~~^^^^^
TypeError: 'Appointment' object is not subscriptable

During handling of the above exception, another exception occurred:

Traceback (most recent call last):
  File "C:\Python312\Lib\site-packages\django\template\base.py", line 893, in _resolve_lookup
    current = getattr(current, bit)
              ^^^^^^^^^^^^^^^^^^^^^
AttributeError: 'Appointment' object has no attribute 'reason'

During handling of the above exception, another exception occurred:

Traceback (most recent call last):
  File "C:\Python312\Lib\site-packages\django\template\base.py", line 899, in _resolve_lookup
    current = current[int(bit)]
                      ^^^^^^^^
ValueError: invalid literal for int() with base 10: 'reason'

During handling of the above exception, another exception occurred:

Traceback (most recent call last):
  File "C:\Python312\Lib\site-packages\django\template\base.py", line 906, in _resolve_lookup
    raise VariableDoesNotExist(
django.template.base.VariableDoesNotExist: Failed lookup for key [reason] in <Appointment: Sickly De Santos - 2024-12-23 09:00>
DEBUG 2024-12-23 20:46:08,375 base 13540 8316 Exception while resolving variable 'reason' in template 'secretary_dash/doctor/dashboard.html'.
Traceback (most recent call last):
  File "C:\Python312\Lib\site-packages\django\template\base.py", line 883, in _resolve_lookup
    current = current[bit]
              ~~~~~~~^^^^^
TypeError: 'Appointment' object is not subscriptable

During handling of the above exception, another exception occurred:

Traceback (most recent call last):
  File "C:\Python312\Lib\site-packages\django\template\base.py", line 893, in _resolve_lookup
    current = getattr(current, bit)
              ^^^^^^^^^^^^^^^^^^^^^
AttributeError: 'Appointment' object has no attribute 'reason'

During handling of the above exception, another exception occurred:

Traceback (most recent call last):
  File "C:\Python312\Lib\site-packages\django\template\base.py", line 899, in _resolve_lookup
    current = current[int(bit)]
                      ^^^^^^^^
ValueError: invalid literal for int() with base 10: 'reason'

During handling of the above exception, another exception occurred:

Traceback (most recent call last):
  File "C:\Python312\Lib\site-packages\django\template\base.py", line 906, in _resolve_lookup
    raise VariableDoesNotExist(
django.template.base.VariableDoesNotExist: Failed lookup for key [reason] in <Appointment: Sickly De Santos - 2024-12-23 09:00>
DEBUG 2024-12-23 20:46:08,376 base 13540 8316 Exception while resolving variable 'reason' in template 'secretary_dash/doctor/dashboard.html'.
Traceback (most recent call last):
  File "C:\Python312\Lib\site-packages\django\template\base.py", line 883, in _resolve_lookup
    current = current[bit]
              ~~~~~~~^^^^^
TypeError: 'Appointment' object is not subscriptable

During handling of the above exception, another exception occurred:

Traceback (most recent call last):
  File "C:\Python312\Lib\site-packages\django\template\base.py", line 893, in _resolve_lookup
    current = getattr(current, bit)
              ^^^^^^^^^^^^^^^^^^^^^
AttributeError: 'Appointment' object has no attribute 'reason'

During handling of the above exception, another exception occurred:

Traceback (most recent call last):
  File "C:\Python312\Lib\site-packages\django\template\base.py", line 899, in _resolve_lookup
    current = current[int(bit)]
                      ^^^^^^^^
ValueError: invalid literal for int() with base 10: 'reason'

During handling of the above exception, another exception occurred:

Traceback (most recent call last):
  File "C:\Python312\Lib\site-packages\django\template\base.py", line 906, in _resolve_lookup
    raise VariableDoesNotExist(
django.template.base.VariableDoesNotExist: Failed lookup for key [reason] in <Appointment: John doe - 2024-12-23 10:30>
DEBUG 2024-12-23 20:46:08,376 base 13540 8316 Exception while resolving variable 'reason' in template 'secretary_dash/doctor/dashboard.html'.
Traceback (most recent call last):
  File "C:\Python312\Lib\site-packages\django\template\base.py", line 883, in _resolve_lookup
    current = current[bit]
              ~~~~~~~^^^^^
TypeError: 'Appointment' object is not subscriptable

During handling of the above exception, another exception occurred:

Traceback (most recent call last):
  File "C:\Python312\Lib\site-packages\django\template\base.py", line 893, in _resolve_lookup
    current = getattr(current, bit)
              ^^^^^^^^^^^^^^^^^^^^^
AttributeError: 'Appointment' object has no attribute 'reason'

During handling of the above exception, another exception occurred:

Traceback (most recent call last):
  File "C:\Python312\Lib\site-packages\django\template\base.py", line 899, in _resolve_lookup
    current = current[int(bit)]
                      ^^^^^^^^
ValueError: invalid literal for int() with base 10: 'reason'

During handling of the above exception, another exception occurred:

Traceback (most recent call last):
  File "C:\Python312\Lib\site-packages\django\template\base.py", line 906, in _resolve_lookup
    raise VariableDoesNotExist(
django.template.base.VariableDoesNotExist: Failed lookup for key [reason] in <Appointment: John doe - 2024-12-23 10:30>
DEBUG 2024-12-23 20:46:08,378 base 13540 8316 Exception while resolving variable 'reason' in template 'secretary_dash/doctor/dashboard.html'.
Traceback (most recent call last):
  File "C:\Python312\Lib\site-packages\django\template\base.py", line 883, in _resolve_lookup
    current = current[bit]
              ~~~~~~~^^^^^
TypeError: 'Appointment' object is not subscriptable

During handling of the above exception, another exception occurred:

Traceback (most recent call last):
  File "C:\Python312\Lib\site-packages\django\template\base.py", line 893, in _resolve_lookup
    current = getattr(current, bit)
              ^^^^^^^^^^^^^^^^^^^^^
AttributeError: 'Appointment' object has no attribute 'reason'

During handling of the above exception, another exception occurred:

Traceback (most recent call last):
  File "C:\Python312\Lib\site-packages\django\template\base.py", line 899, in _resolve_lookup
    current = current[int(bit)]
                      ^^^^^^^^
ValueError: invalid literal for int() with base 10: 'reason'

During handling of the above exception, another exception occurred:

Traceback (most recent call last):
  File "C:\Python312\Lib\site-packages\django\template\base.py", line 906, in _resolve_lookup
    raise VariableDoesNotExist(
django.template.base.VariableDoesNotExist: Failed lookup for key [reason] in <Appointment: psyc D. mann - 2024-12-23 14:00>
DEBUG 2024-12-23 20:46:08,378 base 13540 8316 Exception while resolving variable 'reason' in template 'secretary_dash/doctor/dashboard.html'.
Traceback (most recent call last):
  File "C:\Python312\Lib\site-packages\django\template\base.py", line 883, in _resolve_lookup
    current = current[bit]
              ~~~~~~~^^^^^
TypeError: 'Appointment' object is not subscriptable

During handling of the above exception, another exception occurred:

Traceback (most recent call last):
  File "C:\Python312\Lib\site-packages\django\template\base.py", line 893, in _resolve_lookup
    current = getattr(current, bit)
              ^^^^^^^^^^^^^^^^^^^^^
AttributeError: 'Appointment' object has no attribute 'reason'

During handling of the above exception, another exception occurred:

Traceback (most recent call last):
  File "C:\Python312\Lib\site-packages\django\template\base.py", line 899, in _resolve_lookup
    current = current[int(bit)]
                      ^^^^^^^^
ValueError: invalid literal for int() with base 10: 'reason'

During handling of the above exception, another exception occurred:

Traceback (most recent call last):
  File "C:\Python312\Lib\site-packages\django\template\base.py", line 906, in _resolve_lookup
    raise VariableDoesNotExist(
django.template.base.VariableDoesNotExist: Failed lookup for key [reason] in <Appointment: psyc D. mann - 2024-12-23 14:00>
DEBUG 2024-12-23 20:46:08,379 base 13540 8316 Exception while resolving variable 'reason' in template 'secretary_dash/doctor/dashboard.html'.
Traceback (most recent call last):
  File "C:\Python312\Lib\site-packages\django\template\base.py", line 883, in _resolve_lookup
    current = current[bit]
              ~~~~~~~^^^^^
TypeError: 'Appointment' object is not subscriptable

During handling of the above exception, another exception occurred:

Traceback (most recent call last):
  File "C:\Python312\Lib\site-packages\django\template\base.py", line 893, in _resolve_lookup
    current = getattr(current, bit)
              ^^^^^^^^^^^^^^^^^^^^^
AttributeError: 'Appointment' object has no attribute 'reason'

During handling of the above exception, another exception occurred:

Traceback (most recent call last):
  File "C:\Python312\Lib\site-packages\django\template\base.py", line 899, in _resolve_lookup
    current = current[int(bit)]
                      ^^^^^^^^
ValueError: invalid literal for int() with base 10: 'reason'

During handling of the above exception, another exception occurred:

Traceback (most recent call last):
  File "C:\Python312\Lib\site-packages\django\template\base.py", line 906, in _resolve_lookup
    raise VariableDoesNotExist(
django.template.base.VariableDoesNotExist: Failed lookup for key [reason] in <Appointment: Corey V. Depen - 2024-12-23 16:00>
DEBUG 2024-12-23 20:46:08,379 base 13540 8316 Exception while resolving variable 'reason' in template 'secretary_dash/doctor/dashboard.html'.
Traceback (most recent call last):
  File "C:\Python312\Lib\site-packages\django\template\base.py", line 883, in _resolve_lookup
    current = current[bit]
              ~~~~~~~^^^^^
TypeError: 'Appointment' object is not subscriptable

During handling of the above exception, another exception occurred:

Traceback (most recent call last):
  File "C:\Python312\Lib\site-packages\django\template\base.py", line 893, in _resolve_lookup
    current = getattr(current, bit)
              ^^^^^^^^^^^^^^^^^^^^^
AttributeError: 'Appointment' object has no attribute 'reason'

During handling of the above exception, another exception occurred:

Traceback (most recent call last):
  File "C:\Python312\Lib\site-packages\django\template\base.py", line 899, in _resolve_lookup
    current = current[int(bit)]
                      ^^^^^^^^
ValueError: invalid literal for int() with base 10: 'reason'

During handling of the above exception, another exception occurred:

Traceback (most recent call last):
  File "C:\Python312\Lib\site-packages\django\template\base.py", line 906, in _resolve_lookup
    raise VariableDoesNotExist(
django.template.base.VariableDoesNotExist: Failed lookup for key [reason] in <Appointment: Corey V. Depen - 2024-12-23 16:00>
INFO 2024-12-23 20:46:08,380 basehttp 13540 8316 "GET /doctor/ HTTP/1.1" 200 32368
INFO 2024-12-23 20:46:10,044 basehttp 13540 8316 "GET /doctor/secretaries/ HTTP/1.1" 200 7603
INFO 2024-12-23 20:46:12,393 basehttp 13540 8316 "GET /doctor/secretaries/add/ HTTP/1.1" 200 8510
INFO 2024-12-23 20:46:16,423 basehttp 13540 8316 "GET /patients/ HTTP/1.1" 200 11564
INFO 2024-12-23 20:46:17,149 basehttp 13540 8316 "GET /patients/add/ HTTP/1.1" 200 8159
INFO 2024-12-23 20:46:19,140 basehttp 13540 8316 "GET /medicines/ HTTP/1.1" 200 8526
INFO 2024-12-23 20:46:19,867 basehttp 13540 8316 "GET /medicines/add/ HTTP/1.1" 200 7581
INFO 2024-12-23 20:46:23,468 basehttp 13540 8316 "GET /appointments/ HTTP/1.1" 200 11769
INFO 2024-12-23 20:46:25,019 basehttp 13540 8316 "GET /appointments/add/ HTTP/1.1" 200 8243
DEBUG 2024-12-23 20:46:27,499 base 13540 8316 Exception while resolving variable 'is_completed' in template 'secretary_dash/doctor/examination_list.html'.
Traceback (most recent call last):
  File "C:\Python312\Lib\site-packages\django\template\base.py", line 883, in _resolve_lookup
    current = current[bit]
              ~~~~~~~^^^^^
TypeError: 'Examination' object is not subscriptable

During handling of the above exception, another exception occurred:

Traceback (most recent call last):
  File "C:\Python312\Lib\site-packages\django\template\base.py", line 893, in _resolve_lookup
    current = getattr(current, bit)
              ^^^^^^^^^^^^^^^^^^^^^
AttributeError: 'Examination' object has no attribute 'is_completed'

During handling of the above exception, another exception occurred:

Traceback (most recent call last):
  File "C:\Python312\Lib\site-packages\django\template\base.py", line 899, in _resolve_lookup
    current = current[int(bit)]
                      ^^^^^^^^
ValueError: invalid literal for int() with base 10: 'is_completed'

During handling of the above exception, another exception occurred:

Traceback (most recent call last):
  File "C:\Python312\Lib\site-packages\django\template\base.py", line 906, in _resolve_lookup
    raise VariableDoesNotExist(
django.template.base.VariableDoesNotExist: Failed lookup for key [is_completed] in <Examination: Examination for psyc D. mann on 2024-12-23>
DEBUG 2024-12-23 20:46:27,499 base 13540 8316 Exception while resolving variable 'is_completed' in template 'secretary_dash/doctor/examination_list.html'.
Traceback (most recent call last):
  File "C:\Python312\Lib\site-packages\django\template\base.py", line 883, in _resolve_lookup
    current = current[bit]
              ~~~~~~~^^^^^
TypeError: 'Examination' object is not subscriptable

During handling of the above exception, another exception occurred:

Traceback (most recent call last):
  File "C:\Python312\Lib\site-packages\django\template\base.py", line 893, in _resolve_lookup
    current = getattr(current, bit)
              ^^^^^^^^^^^^^^^^^^^^^
AttributeError: 'Examination' object has no attribute 'is_completed'

During handling of the above exception, another exception occurred:

Traceback (most recent call last):
  File "C:\Python312\Lib\site-packages\django\template\base.py", line 899, in _resolve_lookup
    current = current[int(bit)]
                      ^^^^^^^^
ValueError: invalid literal for int() with base 10: 'is_completed'

During handling of the above exception, another exception occurred:

Traceback (most recent call last):
  File "C:\Python312\Lib\site-packages\django\template\base.py", line 906, in _resolve_lookup
    raise VariableDoesNotExist(
django.template.base.VariableDoesNotExist: Failed lookup for key [is_completed] in <Examination: Examination for psyc D. mann on 2024-12-23>
DEBUG 2024-12-23 20:46:27,504 base 13540 8316 Exception while resolving variable 'is_completed' in template 'secretary_dash/doctor/examination_list.html'.
Traceback (most recent call last):
  File "C:\Python312\Lib\site-packages\django\template\base.py", line 883, in _resolve_lookup
    current = current[bit]
              ~~~~~~~^^^^^
TypeError: 'Examination' object is not subscriptable

During handling of the above exception, another exception occurred:

Traceback (most recent call last):
  File "C:\Python312\Lib\site-packages\django\template\base.py", line 893, in _resolve_lookup
    current = getattr(current, bit)
              ^^^^^^^^^^^^^^^^^^^^^
AttributeError: 'Examination' object has no attribute 'is_completed'

During handling of the above exception, another exception occurred:

Traceback (most recent call last):
  File "C:\Python312\Lib\site-packages\django\template\base.py", line 899, in _resolve_lookup
    current = current[int(bit)]
                      ^^^^^^^^
ValueError: invalid literal for int() with base 10: 'is_completed'

During handling of the above exception, another exception occurred:

Traceback (most recent call last):
  File "C:\Python312\Lib\site-packages\django\template\base.py", line 906, in _resolve_lookup
    raise VariableDoesNotExist(
django.template.base.VariableDoesNotExist: Failed lookup for key [is_completed] in <Examination: Examination for Sickly De Santos on 2024-12-23>
DEBUG 2024-12-23 20:46:27,504 base 13540 8316 Exception while resolving variable 'is_completed' in template 'secretary_dash/doctor/examination_list.html'.
Traceback (most recent call last):
  File "C:\Python312\Lib\site-packages\django\template\base.py", line 883, in _resolve_lookup
    current = current[bit]
              ~~~~~~~^^^^^
TypeError: 'Examination' object is not subscriptable

During handling of the above exception, another exception occurred:

Traceback (most recent call last):
  File "C:\Python312\Lib\site-packages\django\template\base.py", line 893, in _resolve_lookup
    current = getattr(current, bit)
              ^^^^^^^^^^^^^^^^^^^^^
AttributeError: 'Examination' object has no attribute 'is_completed'

During handling of the above exception, another exception occurred:

Traceback (most recent call last):
  File "C:\Python312\Lib\site-packages\django\template\base.py", line 899, in _resolve_lookup
    current = current[int(bit)]
                      ^^^^^^^^
ValueError: invalid literal for int() with base 10: 'is_completed'

During handling of the above exception, another exception occurred:

Traceback (most recent call last):
  File "C:\Python312\Lib\site-packages\django\template\base.py", line 906, in _resolve_lookup
    raise VariableDoesNotExist(
django.template.base.VariableDoesNotExist: Failed lookup for key [is_completed] in <Examination: Examination for Sickly De Santos on 2024-12-23>
DEBUG 2024-12-23 20:46:27,510 base 13540 8316 Exception while resolving variable 'is_completed' in template 'secretary_dash/doctor/examination_list.html'.
Traceback (most recent call last):
  File "C:\Python312\Lib\site-packages\django\template\base.py", line 883, in _resolve_lookup
    current = current[bit]
              ~~~~~~~^^^^^
TypeError: 'Examination' object is not subscriptable

During handling of the above exception, another exception occurred:

Traceback (most recent call last):
  File "C:\Python312\Lib\site-packages\django\template\base.py", line 893, in _resolve_lookup
    current = getattr(current, bit)
              ^^^^^^^^^^^^^^^^^^^^^
AttributeError: 'Examination' object has no attribute 'is_completed'

During handling of the above exception, another exception occurred:

Traceback (most recent call last):
  File "C:\Python312\Lib\site-packages\django\template\base.py", line 899, in _resolve_lookup
    current = current[int(bit)]
                      ^^^^^^^^
ValueError: invalid literal for int() with base 10: 'is_completed'

During handling of the above exception, another exception occurred:

Traceback (most recent call last):
  File "C:\Python312\Lib\site-packages\django\template\base.py", line 906, in _resolve_lookup
    raise VariableDoesNotExist(
django.template.base.VariableDoesNotExist: Failed lookup for key [is_completed] in <Examination: Examination for John doe on 2024-12-23>
DEBUG 2024-12-23 20:46:27,510 base 13540 8316 Exception while resolving variable 'is_completed' in template 'secretary_dash/doctor/examination_list.html'.
Traceback (most recent call last):
  File "C:\Python312\Lib\site-packages\django\template\base.py", line 883, in _resolve_lookup
    current = current[bit]
              ~~~~~~~^^^^^
TypeError: 'Examination' object is not subscriptable

During handling of the above exception, another exception occurred:

Traceback (most recent call last):
  File "C:\Python312\Lib\site-packages\django\template\base.py", line 893, in _resolve_lookup
    current = getattr(current, bit)
              ^^^^^^^^^^^^^^^^^^^^^
AttributeError: 'Examination' object has no attribute 'is_completed'

During handling of the above exception, another exception occurred:

Traceback (most recent call last):
  File "C:\Python312\Lib\site-packages\django\template\base.py", line 899, in _resolve_lookup
    current = current[int(bit)]
                      ^^^^^^^^
ValueError: invalid literal for int() with base 10: 'is_completed'

During handling of the above exception, another exception occurred:

Traceback (most recent call last):
  File "C:\Python312\Lib\site-packages\django\template\base.py", line 906, in _resolve_lookup
    raise VariableDoesNotExist(
django.template.base.VariableDoesNotExist: Failed lookup for key [is_completed] in <Examination: Examination for John doe on 2024-12-23>
DEBUG 2024-12-23 20:46:27,515 base 13540 8316 Exception while resolving variable 'is_completed' in template 'secretary_dash/doctor/examination_list.html'.
Traceback (most recent call last):
  File "C:\Python312\Lib\site-packages\django\template\base.py", line 883, in _resolve_lookup
    current = current[bit]
              ~~~~~~~^^^^^
TypeError: 'Examination' object is not subscriptable

During handling of the above exception, another exception occurred:

Traceback (most recent call last):
  File "C:\Python312\Lib\site-packages\django\template\base.py", line 893, in _resolve_lookup
    current = getattr(current, bit)
              ^^^^^^^^^^^^^^^^^^^^^
AttributeError: 'Examination' object has no attribute 'is_completed'

During handling of the above exception, another exception occurred:

Traceback (most recent call last):
  File "C:\Python312\Lib\site-packages\django\template\base.py", line 899, in _resolve_lookup
    current = current[int(bit)]
                      ^^^^^^^^
ValueError: invalid literal for int() with base 10: 'is_completed'

During handling of the above exception, another exception occurred:

Traceback (most recent call last):
  File "C:\Python312\Lib\site-packages\django\template\base.py", line 906, in _resolve_lookup
    raise VariableDoesNotExist(
django.template.base.VariableDoesNotExist: Failed lookup for key [is_completed] in <Examination: Examination for psyc D. mann on 2024-12-22>
DEBUG 2024-12-23 20:46:27,515 base 13540 8316 Exception while resolving variable 'is_completed' in template 'secretary_dash/doctor/examination_list.html'.
Traceback (most recent call last):
  File "C:\Python312\Lib\site-packages\django\template\base.py", line 883, in _resolve_lookup
    current = current[bit]
              ~~~~~~~^^^^^
TypeError: 'Examination' object is not subscriptable

During handling of the above exception, another exception occurred:

Traceback (most recent call last):
  File "C:\Python312\Lib\site-packages\django\template\base.py", line 893, in _resolve_lookup
    current = getattr(current, bit)
              ^^^^^^^^^^^^^^^^^^^^^
AttributeError: 'Examination' object has no attribute 'is_completed'

During handling of the above exception, another exception occurred:

Traceback (most recent call last):
  File "C:\Python312\Lib\site-packages\django\template\base.py", line 899, in _resolve_lookup
    current = current[int(bit)]
                      ^^^^^^^^
ValueError: invalid literal for int() with base 10: 'is_completed'

During handling of the above exception, another exception occurred:

Traceback (most recent call last):
  File "C:\Python312\Lib\site-packages\django\template\base.py", line 906, in _resolve_lookup
    raise VariableDoesNotExist(
django.template.base.VariableDoesNotExist: Failed lookup for key [is_completed] in <Examination: Examination for psyc D. mann on 2024-12-22>
INFO 2024-12-23 20:46:27,518 basehttp 13540 8316 "GET /examinations/ HTTP/1.1" 200 11698
INFO 2024-12-23 20:46:28,370 basehttp 13540 8316 "GET /examinations/add/ HTTP/1.1" 200 12854
